Workbook
Name dr: [2]DCF!$E$18
Name tg: [2]DCF!$E$19
Name tgr: [3]DCF!$E$19
Name tgr: DCF!$E$19
Name wacc: [3]DCF!$E$18
Name wacc: DCF!$E$18

Sheet Cover
B2: Cover
B3: HDFC Bank
B4: Situation Overview
B6: The Bull Case | D6: =HYPERLINK( "https://finance.yahoo.com/quote/"&SUBSTITUTE(B3," ","")&"/analysis", "Growth Expectations (Yahoo)") -> Growth Expectations (Yahoo)
B7: 1. Largest and most diversified healthcare insurer in the U.S., providing structural and scale advantages
B8: 2. As US population ages, demand for healthcare could boost enrollment and revenues
B9: 3. Lots of bad press with CEO murder and regulatory changes has led to depressed stock price, but recent earnings signaled positive recovery --> good setup for 2026?
B11: The Bear Case | D11: =HYPERLINK( "https://finance.yahoo.com/quote/"&SUBSTITUTE(B8," ","")&"/analysis", "Bear Signals & Red Flags") -> Bear Signals & Red Flags
B12: 1. Regulatory risk with policy changes (especially to Medicare) that negatively impact UNH
B13: 2. Rising medical costs and utilization pressures result in margin compression
B14: 3. Investigations about improper billing practices

Sheet Trading Comparables
B2: Trading Comparables | D2: Date | E2: =TODAY() -> 46055 | G2: WEBSITE | H2: TICKER
E4: Cr. | F4: Cr. | G4: Cr.
X5: Trading Multiples
D6: Current | E6: Share | F6: Enterprise | G6: Market | I6: Revenue | L6: EBITDA | N6: Net Income | Q6: Revenue Growth | S6: EBITDA Margin | U6: Profit Margin | X6: EV / Revenue | Z6: EV / EBITDA | AB6: P / E
B7: Ticker | C7: Company Name | D7: Price | E7: Count | F7: Value | G7: Cap | I7: 2025 | J7: =I7-1 -> 2024 | K7: =J7-1 -> 2023 | L7: =J7 -> 2024 | M7: =K7 -> 2023 | N7: =L7 -> 2024 | O7: =M7 -> 2023 | Q7: =_xlfn.CONCAT(I7,"-",J7) -> 2025-2024 | R7: =_xlfn.CONCAT(J7,"-",K7) -> 2024-2023 | S7: =J7 -> 2024 | T7: =K7 -> 2023 | U7: =S7 -> 2024 | V7: =T7 -> 2023 | X7: =J7 -> 2024 | Y7: =K7 -> 2023 | Z7: =J7 -> 2024 | AA7: =K7 -> 2023 | AB7: =J7 -> 2024 | AC7: =K7 -> 2023
B9: #VALUE! | C9: {=_FV(B9,"Ticker symbol",TRUE)} -> SBIN | D9: {=_FV(B9,"Price")} -> 1018.2 | E9: {=_FV(B9,"Shares outstanding",TRUE)/10000000} -> 923.0617 | F9: 2001956.7 | G9: {=_FV(B9,"Market cap",TRUE)/10000000} -> 949322.9 | H9: =HYPERLINK("https://www.screener.in/company/"&SUBSTITUTE(C9," ","")&"/consolidated/","Financials") -> Financials | I9: 490938 | J9: 439189 | K9: 350845 | L9: 132005.42 | M9: 135923.75 | N9: 100817.87 | O9: 104209.94 | Q9: =J9/I9-1 -> -0.10540842 | R9: =K9/J9-1 -> -0.20115258 | S9: =L9/J9 -> 0.30056632 | T9: =M9/K9 -> 0.38741823 | U9: =N9/J9 -> 0.22955463 | V9: =O9/K9 -> 0.29702558 | X9: =$F9/J9 -> 4.5583035 | Y9: =$F9/K9 -> 5.7061002 | Z9: =$F9/L9 -> 15.165716 | AA9: =$F9/M9 -> 14.728528 | AB9: =$G9/N9 -> 9.4162166 | AC9: =$G9/O9 -> 9.1097154
B11: #VALUE! | C11: {=_FV(B11,"Ticker symbol",TRUE)} -> HDFCBANK | D11: {=_FV(B11,"Price")} -> 922.1 | E11: {=_FV(B11,"Shares outstanding",TRUE)/10000000} -> 1538.68 | G11: {=_FV(B11,"Market cap",TRUE)/10000000} -> 1442067 | H11: =HYPERLINK("https://www.screener.in/company/"&SUBSTITUTE(C11," ","")&"/consolidated/","Financials") -> Financials | Q11: =J11/I11-1 -> #DIV/0! | R11: =K11/J11-1 -> #DIV/0! | S11: =L11/J11 -> #DIV/0! | T11: =M11/K11 -> #DIV/0! | U11: =N11/J11 -> #DIV/0! | V11: =O11/K11 -> #DIV/0! | X11: =$F11/J11 -> #DIV/0! | Y11: =$F11/K11 -> #DIV/0! | Z11: =$F11/L11 -> #DIV/0! | AA11: =$F11/M11 -> #DIV/0! | AB11: =$G11/N11 -> #DIV/0! | AC11: =$G11/O11 -> #DIV/0!
B12: #VALUE! | C12: {=_FV(B12,"Ticker symbol",TRUE)} -> ICICIBANK | D12: {=_FV(B12,"Price")} -> 1334.2 | E12: {=_FV(B12,"Shares outstanding",TRUE)/10000000} -> 715.3235 | G12: {=_FV(B12,"Market cap",TRUE)/10000000} -> 1027296 | H12: =HYPERLINK("https://www.screener.in/company/"&SUBSTITUTE(C12," ","")&"/consolidated/","Financials") -> Financials | Q12: =J12/I12-1 -> #DIV/0! | R12: =K12/J12-1 -> #DIV/0! | S12: =L12/J12 -> #DIV/0! | T12: =M12/K12 -> #DIV/0! | U12: =N12/J12 -> #DIV/0! | V12: =O12/K12 -> #DIV/0! | X12: =$F12/J12 -> #DIV/0! | Y12: =$F12/K12 -> #DIV/0! | Z12: =$F12/L12 -> #DIV/0! | AA12: =$F12/M12 -> #DIV/0! | AB12: =$G12/N12 -> #DIV/0! | AC12: =$G12/O12 -> #DIV/0!
B13: #VALUE! | C13: {=_FV(B13,"Ticker symbol",TRUE)} -> AXISBANK | D13: {=_FV(B13,"Price")} -> 1340.4 | E13: {=_FV(B13,"Shares outstanding",TRUE)/10000000} -> 310.5459 | G13: {=_FV(B13,"Market cap",TRUE)/10000000} -> 391878.8 | H13: =HYPERLINK("https://www.screener.in/company/"&SUBSTITUTE(C13," ","")&"/consolidated/","Financials") -> Financials | Q13: =J13/I13-1 -> #DIV/0! | R13: =K13/J13-1 -> #DIV/0! | S13: =L13/J13 -> #DIV/0! | T13: =M13/K13 -> #DIV/0! | U13: =N13/J13 -> #DIV/0! | V13: =O13/K13 -> #DIV/0! | X13: =$F13/J13 -> #DIV/0! | Y13: =$F13/K13 -> #DIV/0! | Z13: =$F13/L13 -> #DIV/0! | AA13: =$F13/M13 -> #DIV/0! | AB13: =$G13/N13 -> #DIV/0! | AC13: =$G13/O13 -> #DIV/0!
B14: #VALUE! | C14: {=_FV(B14,"Ticker symbol",TRUE)} -> KOTAKBANK | D14: {=_FV(B14,"Price")} -> 407.25 | E14: {=_FV(B14,"Shares outstanding",TRUE)/10000000} -> 1094.646 | G14: {=_FV(B14,"Market cap",TRUE)/10000000} -> 424195.2 | H14: =HYPERLINK("https://www.screener.in/company/"&SUBSTITUTE(C14," ","")&"/consolidated/","Financials") -> Financials | Q14: =J14/I14-1 -> #DIV/0! | R14: =K14/J14-1 -> #DIV/0! | S14: =L14/J14 -> #DIV/0! | T14: =M14/K14 -> #DIV/0! | U14: =N14/J14 -> #DIV/0! | V14: =O14/K14 -> #DIV/0! | X14: =$F14/J14 -> #DIV/0! | Y14: =$F14/K14 -> #DIV/0! | Z14: =$F14/L14 -> #DIV/0! | AA14: =$F14/M14 -> #DIV/0! | AB14: =$G14/N14 -> #DIV/0! | AC14: =$G14/O14 -> #DIV/0!
B15: #VALUE! | C15: {=_FV(B15,"Ticker symbol",TRUE)} -> INDUSINDBK | D15: {=_FV(B15,"Price")} -> 895.6 | E15: {=_FV(B15,"Shares outstanding",TRUE)/10000000} -> 77.9076 | G15: {=_FV(B15,"Market cap",TRUE)/10000000} -> 70938.76 | H15: =HYPERLINK("https://www.screener.in/company/"&SUBSTITUTE(C15," ","")&"/consolidated/","Financials") -> Financials | Q15: =J15/I15-1 -> #DIV/0! | R15: =K15/J15-1 -> #DIV/0! | S15: =L15/J15 -> #DIV/0! | T15: =M15/K15 -> #DIV/0! | U15: =N15/J15 -> #DIV/0! | V15: =O15/K15 -> #DIV/0! | X15: =$F15/J15 -> #DIV/0! | Y15: =$F15/K15 -> #DIV/0! | Z15: =$F15/L15 -> #DIV/0! | AA15: =$F15/M15 -> #DIV/0! | AB15: =$G15/N15 -> #DIV/0! | AC15: =$G15/O15 -> #DIV/0!
B16: #VALUE! | C16: {=_FV(B16,"Ticker symbol",TRUE)} -> BANKBARODA | D16: {=_FV(B16,"Price")} -> 279.7 | E16: {=_FV(B16,"Shares outstanding",TRUE)/10000000} -> 517.1362 | G16: {=_FV(B16,"Market cap",TRUE)/10000000} -> 156097.6 | H16: =HYPERLINK("https://www.screener.in/company/"&SUBSTITUTE(C16," ","")&"/consolidated/","Financials") -> Financials | Q16: =J16/I16-1 -> #DIV/0! | R16: =K16/J16-1 -> #DIV/0! | S16: =L16/J16 -> #DIV/0! | T16: =M16/K16 -> #DIV/0! | U16: =N16/J16 -> #DIV/0! | V16: =O16/K16 -> #DIV/0! | X16: =$F16/J16 -> #DIV/0! | Y16: =$F16/K16 -> #DIV/0! | Z16: =$F16/L16 -> #DIV/0! | AA16: =$F16/M16 -> #DIV/0! | AB16: =$G16/N16 -> #DIV/0! | AC16: =$G16/O16 -> #DIV/0!
B17: #VALUE! | C17: {=_FV(B17,"Ticker symbol",TRUE)} -> PNB | D17: {=_FV(B17,"Price")} -> 121.59 | E17: {=_FV(B17,"Shares outstanding",TRUE)/10000000} -> 1149.294 | G17: {=_FV(B17,"Market cap",TRUE)/10000000} -> 143110.1 | H17: =HYPERLINK("https://www.screener.in/company/"&SUBSTITUTE(C17," ","")&"/consolidated/","Financials") -> Financials | Q17: =J17/I17-1 -> #DIV/0! | R17: =K17/J17-1 -> #DIV/0! | S17: =L17/J17 -> #DIV/0! | T17: =M17/K17 -> #DIV/0! | U17: =N17/J17 -> #DIV/0! | V17: =O17/K17 -> #DIV/0! | X17: =$F17/J17 -> #DIV/0! | Y17: =$F17/K17 -> #DIV/0! | Z17: =$F17/L17 -> #DIV/0! | AA17: =$F17/M17 -> #DIV/0! | AB17: =$G17/N17 -> #DIV/0! | AC17: =$G17/O17 -> #DIV/0!
B18: #VALUE! | C18: {=_FV(B18,"Ticker symbol",TRUE)} -> CANBK | D18: {=_FV(B18,"Price")} -> 141.05 | E18: {=_FV(B18,"Shares outstanding",TRUE)/10000000} -> 907.0651 | G18: {=_FV(B18,"Market cap",TRUE)/10000000} -> 136839.9 | H18: =HYPERLINK("https://www.screener.in/company/"&SUBSTITUTE(C18," ","")&"/consolidated/","Financials") -> Financials | Q18: =J18/I18-1 -> #DIV/0! | R18: =K18/J18-1 -> #DIV/0! | S18: =L18/J18 -> #DIV/0! | T18: =M18/K18 -> #DIV/0! | U18: =N18/J18 -> #DIV/0! | V18: =O18/K18 -> #DIV/0! | X18: =$F18/J18 -> #DIV/0! | Y18: =$F18/K18 -> #DIV/0! | Z18: =$F18/L18 -> #DIV/0! | AA18: =$F18/M18 -> #DIV/0! | AB18: =$G18/N18 -> #DIV/0! | AC18: =$G18/O18 -> #DIV/0!
B19: #VALUE! | C19: {=_FV(B19,"Ticker symbol",TRUE)} -> UNIONBANK | D19: {=_FV(B19,"Price")} -> 169.37 | E19: {=_FV(B19,"Shares outstanding",TRUE)/10000000} -> 763.3605 | G19: {=_FV(B19,"Market cap",TRUE)/10000000} -> 126862.9 | H19: =HYPERLINK("https://www.screener.in/company/"&SUBSTITUTE(C19," ","")&"/consolidated/","Financials") -> Financials | Q19: =J19/I19-1 -> #DIV/0! | R19: =K19/J19-1 -> #DIV/0! | S19: =L19/J19 -> #DIV/0! | T19: =M19/K19 -> #DIV/0! | U19: =N19/J19 -> #DIV/0! | V19: =O19/K19 -> #DIV/0! | X19: =$F19/J19 -> #DIV/0! | Y19: =$F19/K19 -> #DIV/0! | Z19: =$F19/L19 -> #DIV/0! | AA19: =$F19/M19 -> #DIV/0! | AB19: =$G19/N19 -> #DIV/0! | AC19: =$G19/O19 -> #DIV/0!
B20: #VALUE! | C20: {=_FV(B20,"Ticker symbol",TRUE)} -> FEDERALBNK | D20: {=_FV(B20,"Price")} -> 285.1 | E20: {=_FV(B20,"Shares outstanding",TRUE)/10000000} -> 246.2813 | G20: {=_FV(B20,"Market cap",TRUE)/10000000} -> 61385.75 | H20: =HYPERLINK("https://www.screener.in/company/"&SUBSTITUTE(C20," ","")&"/consolidated/","Financials") -> Financials | Q20: =J20/I20-1 -> #DIV/0! | R20: =K20/J20-1 -> #DIV/0! | S20: =L20/J20 -> #DIV/0! | T20: =M20/K20 -> #DIV/0! | U20: =N20/J20 -> #DIV/0! | V20: =O20/K20 -> #DIV/0! | X20: =$F20/J20 -> #DIV/0! | Y20: =$F20/K20 -> #DIV/0! | Z20: =$F20/L20 -> #DIV/0! | AA20: =$F20/M20 -> #DIV/0! | AB20: =$G20/N20 -> #DIV/0! | AC20: =$G20/O20 -> #DIV/0!
B21: #VALUE! | C21: {=_FV(B21,"Ticker symbol",TRUE)} -> IDFCFIRSTB | D21: {=_FV(B21,"Price")} -> 82.03 | E21: {=_FV(B21,"Shares outstanding",TRUE)/10000000} -> 859.7745 | G21: {=_FV(B21,"Market cap",TRUE)/10000000} -> 71317.84 | H21: =HYPERLINK("https://www.screener.in/company/"&SUBSTITUTE(C21," ","")&"/consolidated/","Financials") -> Financials | Q21: =J21/I21-1 -> #DIV/0! | R21: =K21/J21-1 -> #DIV/0! | S21: =L21/J21 -> #DIV/0! | T21: =M21/K21 -> #DIV/0! | U21: =N21/J21 -> #DIV/0! | V21: =O21/K21 -> #DIV/0! | X21: =$F21/J21 -> #DIV/0! | Y21: =$F21/K21 -> #DIV/0! | Z21: =$F21/L21 -> #DIV/0! | AA21: =$F21/M21 -> #DIV/0! | AB21: =$G21/N21 -> #DIV/0! | AC21: =$G21/O21 -> #DIV/0!
B23: Mean | Q23: =AVERAGE(Q11:Q21) -> #DIV/0! | R23: =AVERAGE(R11:R21) -> #DIV/0! | S23: =AVERAGE(S11:S21) -> #DIV/0! | T23: =AVERAGE(T11:T21) -> #DIV/0! | U23: =AVERAGE(U11:U21) -> #DIV/0! | V23: =AVERAGE(V11:V21) -> #DIV/0! | X23: =AVERAGE(X11:X21) -> #DIV/0! | Y23: =AVERAGE(Y11:Y21) -> #DIV/0! | Z23: =AVERAGE(Z11:Z21) -> #DIV/0! | AA23: =AVERAGE(AA11:AA21) -> #DIV/0! | AB23: =AVERAGE(AB11:AB21) -> #DIV/0! | AC23: =AVERAGE(AC11:AC21) -> #DIV/0!
B24: Median | Q24: =MEDIAN(Q11:Q21) -> #DIV/0! | R24: =MEDIAN(R11:R21) -> #DIV/0! | S24: =MEDIAN(S11:S21) -> #DIV/0! | T24: =MEDIAN(T11:T21) -> #DIV/0! | U24: =MEDIAN(U11:U21) -> #DIV/0! | V24: =MEDIAN(V11:V21) -> #DIV/0! | X24: =MEDIAN(X11:X21) -> #DIV/0! | Y24: =MEDIAN(Y11:Y21) -> #DIV/0! | Z24: =MEDIAN(Z11:Z21) -> #DIV/0! | AA24: =MEDIAN(AA11:AA21) -> #DIV/0! | AB24: =MEDIAN(AB11:AB21) -> #DIV/0! | AC24: =MEDIAN(AC11:AC21) -> #DIV/0!
B26: https://www.nseindia.com/static/market-data/securities-available-for-trading

Sheet WACC
B2: WACC
B4: WACC = % of equity x cost of equity + % of debt x cost of debt x (1 - Tax Rate)
B5: Cost of equity = Risk free rate + Beta x Market Risk Premium
D7: Market | E7: Equity | F7: Cost of | G7: Risk Free | H7: Beta | I7: Market Risk | J7: Debt | K7: Debt | L7: Cost of | M7: Tax Rate | N7: Total | O7: WACC
B8: Ticker | C8: Company Name | D8: Cap | E8: % | F8: Equity | G8: Rate | I8: Premium | K8: % | L8: Debt
G9: =HYPERLINK("https://tradingeconomics.com/india/government-bond-yield","India 10Y Yield") -> India 10Y Yield | I9: =HYPERLINK("https://pages.stern.nyu.edu/~adamodar/New_Home_Page/datafile/ctryprem.html","Country Risk Premium") -> Country Risk Premium | J9: =HYPERLINK("https://www.screener.in/company/SBIN/consolidated/#balance-sheet","Debt") -> Debt
B10: #VALUE! | C10: {=_FV(B10,"Ticker symbol",TRUE)} -> SBIN | D10: {=_FV(B10,"Price")} -> 1018.2 | G10: 0.067 | H10: {=_FV(B10,"Beta")} -> 1.2209 | I10: 0.0708 | J10: 490938 | K10: 439189 | L10: 350845 | M10: 132005.42 | N10: 135923.75 | O10: 100817.87
B12: #VALUE! | C12: {=_FV(B12,"Ticker symbol",TRUE)} -> HDFCBANK | D12: {=_FV(B12,"Price")} -> 922.1 | G12: 0.067 | I12: 0.0708
B13: #VALUE! | C13: {=_FV(B13,"Ticker symbol",TRUE)} -> ICICIBANK | D13: {=_FV(B13,"Price")} -> 1334.2 | G13: 0.067 | I13: 0.0708
B14: #VALUE! | C14: {=_FV(B14,"Ticker symbol",TRUE)} -> AXISBANK | D14: {=_FV(B14,"Price")} -> 1340.4 | G14: 0.067 | I14: 0.0708
B15: #VALUE! | C15: {=_FV(B15,"Ticker symbol",TRUE)} -> KOTAKBANK | D15: {=_FV(B15,"Price")} -> 407.25 | G15: 0.067 | I15: 0.0708
B16: #VALUE! | C16: {=_FV(B16,"Ticker symbol",TRUE)} -> INDUSINDBK | D16: {=_FV(B16,"Price")} -> 895.6 | G16: 0.067 | I16: 0.0708
B18: Mean
B19: Median

Sheet DCF
B2: DCF
B4: Ticker | C4: UNH | E4: Current Stock Price | H4: =#REF! -> #REF!
B5: Date | C5: 46001 | E5: Implied Share Price | H5: =P84 -> #REF!
B6: Year End | C6: 46022 | E6: Upside / (Downside) | H6: =H5/H4-1 -> #REF!
A8: x | B8: Assumptions
B10: Switches | G10: Conservative | L10: Base | Q10: Optimistic
B11: Assumptions | G11: Assumptions | I11: Year | J11: Metric | L11: Assumptions | N11: Year | O11: Metric | Q11: Assumptions | S11: Year | T11: Metric
B12: Revenue | E12: 2 | G12: Revenue (% of base) | I12: '26-'27 | J12: 0.85 | Q12: Revenue (% of base) | S12: '26-'27 | T12: 1.15
B13: EBIT | E13: 2 | G13: Revenue (decel.) | I13: '28-'30 | J13: -0.1 | L13: Revenue (decel.) | N13: '28-'30 | O13: -0.05 | Q13: Revenue (decel.) | S13: '28-'30 | T13: -0.025
B14: WACC | E14: 1 | G14: EBIT (% of base) | I14: '26-'27 | J14: 0.95 | Q14: EBIT (% of base) | S14: '26-'27 | T14: 1.05
B15: TGR | E15: 2 | G15: EBIT (growth) | I15: '28-'30 | J15: 0.055 | L15: EBIT (growth) | N15: '28-'30 | O15: 0.07 | Q15: EBIT (growth) | S15: '28-'30 | T15: 0.085
B17: Valuation
B18: WACC | E18: =CHOOSE(E14,J18,O18,T18) -> #REF! | G18: WACC | J18: =O18+1% -> #REF! | L18: WACC | O18: =T18+2.5% -> #REF! | Q18: WACC | T18: =WACC!#REF! -> #REF!
B19: TGR | E19: =CHOOSE(E15,J19,O19,T19) -> 0.02 | G19: TGR | J19: 0.015 | L19: TGR | O19: 0.02 | Q19: TGR | T19: 0.025
A21: x | B21: Income Statement (12/31) | E21: 2019 | F21: =E21+1 -> 2020 | G21: =F21+1 -> 2021 | H21: =G21+1 -> 2022 | I21: =H21+1 -> 2023 | J21: =I21+1 -> 2024 | K21: =J21+1 -> 2025 | L21: =K21+1 -> 2026 | M21: =L21+1 -> 2027 | ... O21: =N21+1 -> 2029
B22: Revenue | E22: ='IS - Estimates'!B5 -> 242155 | F22: ='IS - Estimates'!C5 -> 257141 | G22: ='IS - Estimates'!D5 -> 287597 | H22: ='IS - Estimates'!E5 -> 324162 | I22: ='IS - Estimates'!F5 -> 371622 | J22: ='IS - Estimates'!G5 -> 400278 | K22: ='IS - Estimates'!H5 -> 447440 | L22: ='IS - Estimates'!I5 -> 453201 | ... O22: ='IS - Estimates'!L5 -> 533966
B23: % growth | F23: =F22/E22-1 -> 0.061885982 | G23: =G22/F22-1 -> 0.11844086 | H23: =H22/G22-1 -> 0.12713971 | I23: =I22/H22-1 -> 0.14640828 | J23: =J22/I22-1 -> 0.077110612 | K23: =K22/J22-1 -> 0.11782311 | L23: =L22/K22-1 -> 0.012875469 | M23: =M22/L22-1 -> 0.053309679 | ... O23: =O22/N22-1 -> 0.079170481
B25: EBIT | E25: ='IS - Estimates'!B10 -> 19685 | F25: ='IS - Estimates'!C10 -> 22405 | G25: ='IS - Estimates'!D10 -> 23970 | H25: ='IS - Estimates'!E10 -> 28435 | I25: ='IS - Estimates'!F10 -> 32358 | J25: ='IS - Estimates'!G10 -> 32287 | K25: ='IS - Estimates'!H10 -> 22264.5 | L25: ='IS - Estimates'!I10 -> 24113.8 | ... O25: ='IS - Estimates'!L10 -> 37521.3
B26: % of sales | E26: =E25/E22 -> 0.081290909 | F26: =F25/F22 -> 0.087131185 | G26: =G25/G22 -> 0.083345793 | H26: =H25/H22 -> 0.087718486 | I26: =I25/I22 -> 0.087072348 | J26: =J25/J22 -> 0.08066144 | K26: =K25/K22 -> 0.049759744 | L26: =L25/L22 -> 0.053207738 | ... O26: =O25/O22 -> 0.070269081
B28: Taxes | E28: =-'IS - Historicals'!F23 -> 3742 | F28: =-'IS - Historicals'!G23 -> 4973 | G28: =-'IS - Historicals'!H23 -> 4578 | H28: =-'IS - Historicals'!I23 -> 5704 | I28: =-'IS - Historicals'!J23 -> 5968 | J28: =-'IS - Historicals'!K23 -> 4829
B29: Tax rate | E29: =-'IS - Historicals'!F23/'IS - Historicals'!F22 -> 0.20810856 | F29: =-'IS - Historicals'!G23/'IS - Historicals'!G22 -> 0.23975509 | G29: =-'IS - Historicals'!H23/'IS - Historicals'!H22 -> 0.20519946 | H29: =-'IS - Historicals'!I23/'IS - Historicals'!I22 -> 0.21652811 | I29: =-'IS - Historicals'!J23/'IS - Historicals'!J22 -> 0.20500137 | J29: =-'IS - Historicals'!K23/'IS - Historicals'!K22 -> 0.24059588
A31: x | B31: Cash Flow Items (12/31) | E31: 2019 | F31: =E31+1 -> 2020 | G31: =F31+1 -> 2021 | H31: =G31+1 -> 2022 | I31: =H31+1 -> 2023 | J31: =I31+1 -> 2024
B32: D&A | E32: ='CFS - Historicals'!F12 -> 2720 | F32: ='CFS - Historicals'!G12 -> 2891 | G32: ='CFS - Historicals'!H12 -> 3103 | H32: ='CFS - Historicals'!I12 -> 3400 | I32: ='CFS - Historicals'!J12 -> 3972 | J32: ='CFS - Historicals'!K12 -> 4099
B33: % of sales | E33: =E32/E$22 -> 0.011232475 | F33: =F32/F$22 -> 0.011242859 | G33: =G32/G$22 -> 0.010789403 | H33: =H32/H$22 -> 0.010488583 | I33: =I32/I$22 -> 0.01068828 | J33: =J32/J$22 -> 0.010240383
B35: CapEx | E35: =-'CFS - Historicals'!F42 -> 2071 | F35: =-'CFS - Historicals'!G42 -> 2051 | G35: =-'CFS - Historicals'!H42 -> 2454 | H35: =-'CFS - Historicals'!I42 -> 2802 | I35: =-'CFS - Historicals'!J42 -> 3386 | J35: =-'CFS - Historicals'!K42 -> 3499
B36: % of sales | E36: =E35/E$22 -> 0.0085523735 | F36: =F35/F$22 -> 0.0079761687 | G36: =G35/G$22 -> 0.0085327733 | H36: =H35/H$22 -> 0.0086438262 | I36: =I35/I$22 -> 0.0091114089 | J36: =J35/J$22 -> 0.0087414247
B38: Change in NWC | E38: ='CFS - Historicals'!F19 -> 683 | F38: ='CFS - Historicals'!G19 -> 2895 | G38: ='CFS - Historicals'!H19 -> 1522 | H38: ='CFS - Historicals'!I19 -> 2246 | I38: ='CFS - Historicals'!J19 -> 1643 | J38: ='CFS - Historicals'!K19 -> -808
B39: % of sales | E39: =E38/E$22 -> 0.0028205075 | F39: =F38/F$22 -> 0.011258415 | G39: =G38/G$22 -> 0.0052921275 | H39: =H38/H$22 -> 0.0069286344 | I39: =I38/I$22 -> 0.0044211591 | J39: =J38/J$22 -> -0.0020185971
B40: % of change in sales | F40: =F38/(F22-E22) -> 0.1931803 | G40: =G38/(G22-F22) -> 0.049973733 | H40: =H38/(H22-G22) -> 0.06142486 | I40: =I38/(I22-H22) -> 0.034618626 | J40: =J38/(J22-I22) -> -0.028196538
K41: 1 | L41: =K41+1 -> 2 | M41: =L41+1 -> 3 | N41: =M41+1 -> 4 | O41: =N41+1 -> 5 | P41: =O41+1 -> 6
A42: x | B42: DCF (12/31, USD M) | E42: 2019 | F42: =E42+1 -> 2020 | G42: =F42+1 -> 2021 | H42: =G42+1 -> 2022 | I42: =H42+1 -> 2023 | J42: =I42+1 -> 2024 | K42: =J42+1 -> 2025 | L42: =K42+1 -> 2026 | M42: =L42+1 -> 2027 | ... P42: =O42+1 -> 2030
B43: Revenue | E43: =E22 -> 242155 | F43: =F22 -> 257141 | G43: =G22 -> 287597 | H43: =H22 -> 324162 | I43: =I22 -> 371622 | J43: =J22 -> 400278 | K43: =J43*(1+K44) -> 447440 | L43: =K43*(1+L44) -> 453201 | M43: =L43*(1+M44) -> 477361 | N43: =M43*(1+N44) -> 501536.56 | O43: =N43*(1+O44) -> 525666.48 | P43: =O43*(1+P44) -> 549692.8
B44: % growth | F44: =F43/E43-1 -> 0.061885982 | G44: =G43/F43-1 -> 0.11844086 | H44: =H43/G43-1 -> 0.12713971 | I44: =I43/H43-1 -> 0.14640828 | J44: =J43/I43-1 -> 0.077110612 | K44: =OFFSET(K44,$E$12,0) -> 0.11782311 | L44: =OFFSET(L44,$E$12,0) -> 0.012875469 | M44: =OFFSET(M44,$E$12,0) -> 0.053309679 | N44: =OFFSET(N44,$E$12,0) -> 0.050644195 | O44: =OFFSET(O44,$E$12,0) -> 0.048111986 | P44: =OFFSET(P44,$E$12,0) -> 0.045706386
B45: Conservative | K45: =$K$23 -> 0.11782311 | L45: =L46*$J$12 -> 0.010944149 | M45: =M46*$J$12 -> 0.045313227 | N45: =M45*(1+$J$13) -> 0.040781905 | O45: =N45*(1+$J$13) -> 0.036703714 | P45: =O45*(1+$J$13) -> 0.033033343
B46: Base (Street) | K46: =$K$23 -> 0.11782311 | L46: =L23 -> 0.012875469 | M46: =M23 -> 0.053309679 | N46: =M46*(1+$O$13) -> 0.050644195 | O46: =N46*(1+$O$13) -> 0.048111986 | P46: =O46*(1+$O$13) -> 0.045706386
B47: Optimistic | K47: =$K$23 -> 0.11782311 | L47: =L46*$T$12 -> 0.01480679 | M47: =M46*$T$12 -> 0.061306131 | N47: =M47*(1+$T$13) -> 0.059773478 | O47: =N47*(1+$T$13) -> 0.058279141 | P47: =O47*(1+$T$13) -> 0.056822163
B49: EBIT | E49: =E25 -> 19685 | F49: =F25 -> 22405 | G49: =G25 -> 23970 | H49: =H25 -> 28435 | I49: =I25 -> 32358 | J49: =J25 -> 32287 | K49: =K50*K43 -> 22264.5 | L49: =L50*L43 -> 24113.8 | M49: =M50*M43 -> 27545.4 | N49: =N50*N43 -> 30966.244 | O49: =O50*O43 -> 34728.017 | P49: =P50*P43 -> 38857.381
B50: % of sales | E50: =E49/E$43 -> 0.081290909 | F50: =F49/F$43 -> 0.087131185 | G50: =G49/G$43 -> 0.083345793 | H50: =H49/H$43 -> 0.087718486 | I50: =I49/I$43 -> 0.087072348 | J50: =J49/J$43 -> 0.08066144 | K50: =OFFSET(K50,$E$13,0) -> 0.049759744 | L50: =OFFSET(L50,$E$13,0) -> 0.053207738 | M50: =OFFSET(M50,$E$13,0) -> 0.057703499 | N50: =OFFSET(N50,$E$13,0) -> 0.061742744 | O50: =OFFSET(O50,$E$13,0) -> 0.066064736 | P50: =OFFSET(P50,$E$13,0) -> 0.070689268
B51: Conservative | K51: =$K$26 -> 0.049759744 | L51: =L52*$J$14 -> 0.050547351 | M51: =M52*$J$14 -> 0.054818324 | N51: =M51*(1+$J$15) -> 0.057833332 | O51: =N51*(1+$J$15) -> 0.061014165 | P51: =O51*(1+$J$15) -> 0.064369944
B52: Base (Street) | K52: =$K$26 -> 0.049759744 | L52: =L26 -> 0.053207738 | M52: =M26 -> 0.057703499 | N52: =M52*(1+$O$15) -> 0.061742744 | O52: =N52*(1+$O$15) -> 0.066064736 | P52: =O52*(1+$O$15) -> 0.070689268
...

Sheet Shares
B2: Diluted Share Count Calculation
A4: x | B4: Full Diluted Shares
B6: Current price | E6: =#REF! -> #REF!
B7: Basic shares outstanding (latest filing) | E7: 905.83862
B8: In-the-money exercisable options | E8: =E32 -> #REF!
B9: Total proceeds ($mm) | E9: =SUMPRODUCT(D21:D30,E21:E30) -> #REF!
B10: Total shares repurchased (mm) | E10: =E9/E6 -> #REF!
B11: Net dilutive options | E11: =E8-E10 -> #REF!
B13: RSUs | E13: 4
B14: PSUs
B16: Net diluted shares outstanding | E16: =E7+E11+E13+E14 -> #REF!
A18: x | B18: Options outstanding
C20: Outstanding | D20: Exercise price | E20: Dilutive Shares
B21: 1 | C21: 17 | D21: 370 | E21: =IF(D21<$E$6,C21) -> #REF!
B22: =B21+1 -> 2 | E22: =IF(D22<$E$6,C22) -> #REF!
B23: =B22+1 -> 3 | E23: =IF(D23<$E$6,C23) -> #REF!
B24: =B23+1 -> 4 | E24: =IF(D24<$E$6,C24) -> #REF!
B25: =B24+1 -> 5 | E25: =IF(D25<$E$6,C25) -> #REF!
B26: =B25+1 -> 6 | E26: =IF(D26<$E$6,C26) -> #REF!
B27: =B26+1 -> 7 | E27: =IF(D27<$E$6,C27) -> #REF!
B28: =B27+1 -> 8 | E28: =IF(D28<$E$6,C28) -> #REF!
B29: =B28+1 -> 9 | E29: =IF(D29<$E$6,C29) -> #REF!
B30: =B29+1 -> 10 | E30: =IF(D30<$E$6,C30) -> #REF!
A32: x | B32: Total | E32: =SUM(E21:E30) -> #REF!

Sheet IS - Estimates
A1: UNH-US
A2: Income Statement (M)
B3: CY '19 | C3: CY '20 | D3: CY '21 | E3: CY '22 | F3: CY '23 | G3: CY '24 | H3: CY '25E | I3: CY '26E | J3: CY '27E | K3: CY '28E | L3: CY '29E | M3: CY '30E
B4: Dec '19 | C4: Dec '20 | D4: Dec '21 | E4: Dec '22 | F4: Dec '23 | G4: Dec '24 | H4: Dec '25E | I4: Dec '26E | J4: Dec '27E | K4: Dec '28E | L4: Dec '29E | M4: Dec '30E
A5: Sales | B5: 242155 | C5: 257141 | D5: 287597 | E5: 324162 | F5: 371622 | G5: 400278 | H5: 447440 | I5: 453201 | J5: 477361 | K5: 494793 | L5: 533966 | M5: -
A6: Cost of Sales | B6: 28117 | C6: 30745 | D6: 31034 | E6: 33703 | F6: 38770 | G6: 46694 | H6: 51000.3 | I6: 52392 | J6: 54166.5 | K6: 43887.3 | L6: 66353 | M6: -
A7: Gross Income | B7: 55712 | C7: 65498 | D7: - | E7: - | F7: 90973.1 | G7: - | H7: 82192 | I7: 84958 | J7: - | K7: - | L7: - | M7: -
A8: Compensation and Benefits | B8: - | C8: - | D8: 186911 | E8: 210842 | F8: 241894 | G8: 263555 | H8: 312560 | I8: 325076 | J8: 335516 | K8: 356410 | L8: 381008 | M8: -
A9: EBITDA | B9: 22405 | C9: 25296 | D9: 27073 | E9: 31835 | F9: 36330 | G9: 38619 | H9: 26429.5 | I9: 28395.5 | J9: 31995.8 | K9: 37493.3 | L9: 42668.3 | M9: -
A10: Operating Income | B10: 19685 | C10: 22405 | D10: 23970 | E10: 28435 | F10: 32358 | G10: 32287 | H10: 22264.5 | I10: 24113.8 | J10: 27545.4 | K10: 33993.8 | L10: 37521.3 | M10: -
A11: Pretax Income | B11: 17981 | C11: 20742 | D11: 22310 | E11: 26343 | F11: 29112 | G11: 30614 | H11: 17931.1 | I11: 20124.1 | J11: 23546.2 | K11: 28812 | L11: 33112.3 | M11: -
A12: Tax Expense | B12: 3742 | C12: 4973 | D12: 4578 | E12: 5704 | F12: 5968 | G12: 4829 | H12: 3267.17 | I12: 4154.58 | J12: 4944 | K12: 6125.5 | L12: 7151.5 | M12: -
A13: Net Income | B13: 13839 | C13: 15403 | D13: 17285 | E13: 20120 | F13: 22381 | G13: 14405 | H13: 14025.5 | I13: 15338.3 | J13: 17878.9 | K13: 22138.6 | L13: 25605.7 | M13: -

Sheet IS - Historicals
A1: UnitedHealth Group Incorporated (UNH)
A2: $324.37
A5: UnitedHealth Group Incorporated
A6: UNH 91324P102 2917766 NYSE Common stock
A7: FactSet Fundamentals
B8: 31 DEC '15 | C8: 31 DEC '16 | D8: 31 DEC '17 | E8: 31 DEC '18 | F8: 31 DEC '19 | G8: 31 DEC '20 | H8: 31 DEC '21 | I8: 31 DEC '22 | J8: 31 DEC '23 | K8: 31 DEC '24
A9: Total revenues | B9: 157107 | C9: 184840 | D9: 201159 | E9: 226247 | F9: 242155 | G9: 257141 | H9: 287597 | I9: 324162 | J9: 371622 | K9: 400278
A10: Premiums | B10: 127163 | C10: 144118 | D10: 158453 | E10: 178087 | F10: 189699 | G10: 201478 | H10: 226233 | I10: 257157 | J10: 290827 | K10: 308810
A11: Products | B11: 17312 | C11: 26658 | D11: 26366 | E11: 29601 | F11: 31597 | G11: 34145 | H11: 34437 | I11: 37424 | J11: 42583 | K11: 50226
A12: Services | B12: 11922 | C12: 13236 | D12: 15317 | E12: 17183 | F12: 18973 | G12: 20016 | H12: 24603 | I12: 27551 | J12: 34123 | K12: 36040
A13: Investment and other income | B13: 710 | C13: 828 | D13: 1023 | E13: 1376 | F13: 1886 | G13: 1502 | H13: 2324 | I13: 2030 | J13: 4089 | K13: 5202
A14: Total operating costs | B14: -146086 | C14: -171910 | D14: -185950 | E14: -208903 | F14: -222470 | G14: -234736 | H14: -263627 | I14: -295727 | J14: -339264 | K14: -367991
A15: Medical costs | B15: -103875 | C15: -117038 | D15: -130036 | E15: -145403 | F15: -156440 | G15: -159396 | H15: -186911 | I15: -210842 | J15: -241894 | K15: -264185
A16: Operating costs | B16: -24312 | C16: -28401 | D16: -29557 | E16: -34074 | F16: -35193 | G16: -41704 | H16: -42579 | I16: -47782 | J16: -54628 | K16: -53013
A17: Cost of products sold | B17: -16206 | C17: -24416 | D17: -24112 | E17: -26998 | F17: -28117 | G17: -30745 | H17: -31034 | I17: -33703 | J17: -38770 | K17: -46694
A18: Depreciation and amortization | B18: -1693 | C18: -2055 | D18: -2245 | E18: -2428 | F18: -2720 | G18: -2891 | H18: -3103 | I18: -3400 | J18: -3972 | K18: -4099
A19: Earnings from operations | B19: 11021 | C19: 12930 | D19: 15209 | E19: 17344 | F19: 19685 | G19: 22405 | H19: 23970 | I19: 28435 | J19: 32358 | K19: 32287
A20: Interest expense | B20: -790 | C20: -1067 | D20: -1186 | E20: -1400 | F20: -1704 | G20: -1663 | H20: -1660 | I20: -2092 | J20: -3246 | K20: -3906
A21: Loss on sale of subsidiary | B21: - | C21: - | D21: - | E21: - | F21: - | G21: - | H21: - | I21: - | J21: - | K21: -8310
A22: Earnings before income taxes | B22: 10231 | C22: 11863 | D22: 14023 | E22: 15944 | F22: 17981 | G22: 20742 | H22: 22310 | I22: 26343 | J22: 29112 | K22: 20071
A23: Provision for income taxes | B23: -4363 | C23: -4790 | D23: -3200 | E23: -3562 | F23: -3742 | G23: -4973 | H23: -4578 | I23: -5704 | J23: -5968 | K23: -4829
A24: Net earnings | B24: 5868 | C24: 7073 | D24: 10823 | E24: 12382 | F24: 14239 | G24: 15769 | H24: 17732 | I24: 20639 | J24: 23144 | K24: 15242
A25: Earnings attributable to noncontrolling interests | B25: -55 | C25: -56 | D25: -265 | E25: -396 | F25: -400 | G25: -366 | H25: -447 | I25: -519 | J25: -763 | K25: -837
A26: Net earnings attributable to UnitedHealth Group common shareholders | B26: 5813 | C26: 7017 | D26: 10558 | E26: 11986 | F26: 13839 | G26: 15403 | H26: 17285 | I26: 20120 | J26: 22381 | K26: 14405
A27: Per share
A28: Basic | B28: 6.1 | C28: 7.37 | D28: 10.95 | E28: 12.45 | F28: 14.55 | G28: 16.23 | H28: 18.33 | I28: 21.47 | J28: 24.12 | K28: 15.64
A29: Diluted | B29: 6.01 | C29: 7.25 | D29: 10.72 | E29: 12.19 | F29: 14.33 | G29: 16.03 | H29: 18.08 | I29: 21.18 | J29: 23.86 | K29: 15.51
A30: Weighted average shares
A31: Basic | B31: 953 | C31: 952 | D31: 964 | E31: 963 | F31: 951 | G31: 949 | H31: 943 | I31: 937 | J31: 928 | K31: 921
A32: Diluted | B32: 967 | C32: 968 | D32: 985 | E32: 983 | F32: 966 | G32: 961 | H32: 956 | I32: 950 | J32: 938 | K32: 929
A33: All figures in millions of U.S. Dollar except per share items.

Sheet CFS - Estimates
A1: UNH-US
A2: Cash Flow (M)
B3: CY '19 | C3: CY '20 | D3: CY '21 | E3: CY '22 | F3: CY '23 | G3: CY '24 | H3: CY '25E | I3: CY '26E | J3: CY '27E | K3: CY '28E | L3: CY '29E | M3: CY '30E
B4: Dec '19 | C4: Dec '20 | D4: Dec '21 | E4: Dec '22 | F4: Dec '23 | G4: Dec '24 | H4: Dec '25E | I4: Dec '26E | J4: Dec '27E | K4: Dec '28E | L4: Dec '29E | M4: Dec '30E
A5: Capital Expenditures | B5: 2071 | C5: 2089.11 | D5: 2416.46 | E5: 2703.76 | F5: 3386 | G5: 3499 | H5: 3689.5 | I5: 3906.17 | J5: 4096.62 | K5: 3858.5 | L5: 4027 | M5: -
A6: Free Cash Flow | B6: 15992 | C6: 20123 | D6: 20548.5 | E6: 25043 | F6: 25300.5 | G6: 23444 | H6: 19858.5 | I6: 18181.2 | J6: 21505.8 | K6: 24258.6 | L6: 27146 | M6: -
A7: Cash Flow from Operations | B7: 18263 | C7: 19929.5 | D7: 22343 | E7: 26206 | F7: 29068 | G7: 24204 | H7: 18597.8 | I7: 20819 | J7: 25273.5 | K7: 30012 | L7: 35152 | M7: -
A8: Cash Flow from Investing | B8: -12699 | C8: -12532 | D8: -10372 | E8: -28476 | F8: -15574 | G8: -20527 | H8: -8197.5 | I8: -10569 | J8: -8634 | K8: -13591 | L8: -13691 | M8: -
A9: Cash Flow from Financing | B9: -5625 | C9: -3590 | D9: -7455 | E9: 2507 | F9: -11529 | G9: - | H9: -13350.5 | I9: -10570.5 | J9: -15232 | K9: -14965 | L9: -17364 | M9: -

Sheet CFS  - Historicals
A1: UnitedHealth Group Incorporated (UNH)
A2: $324.90
A5: UnitedHealth Group Incorporated
A6: UNH 91324P102 2917766 NYSE Common stock
A7: FactSet Fundamentals
B8: 31 DEC '15 | C8: 31 DEC '16 | D8: 31 DEC '17 | E8: 31 DEC '18 | F8: 31 DEC '19 | G8: 31 DEC '20 | H8: 31 DEC '21 | I8: 31 DEC '22 | J8: 31 DEC '23 | K8: 31 DEC '24
A9: Cash flows from operating activities | B9: 9740 | C9: 9795 | D9: 13596 | E9: 15713 | F9: 18463 | G9: 22174 | H9: 22343 | I9: 26206 | J9: 29068 | K9: 24204
A10: Net earnings | B10: 5868 | C10: 7073 | D10: 10823 | E10: 12382 | F10: 14239 | G10: 15769 | H10: 17732 | I10: 20639 | J10: 23144 | K10: 15242
A11: Noncash items | B11: 1791 | C11: 2539 | D11: 2094 | E11: 3037 | F11: 3541 | G11: 3510 | H11: 3089 | I11: 3321 | J11: 4281 | K11: 9770
A12: Depreciation and amortization | B12: 1693 | C12: 2055 | D12: 2245 | E12: 2428 | F12: 2720 | G12: 2891 | H12: 3103 | I12: 3400 | J12: 3972 | K12: 4099
A13: Deferred income taxes and other | B13: -308 | C13: -1 | D13: -748 | E13: -29 | F13: 124 | G13: -60 | H13: -814 | I13: -1004 | J13: -750 | K13: -3657
A14: Deferred income taxes | B14: -73 | C14: 81 | D14: -965 | E14: 42 | F14: 230 | G14: -8 | H14: 130 | I14: -673 | J14: -245 | K14: -296
A15: Gains on dispositions and other strategic transactions | B15: - | C15: - | D15: - | E15: - | F15: - | G15: - | H15: - | I15: - | J15: - | K15: -3333
A16: Other, net | B16: -235 | C16: -82 | D16: 217 | E16: -71 | F16: -106 | G16: -52 | H16: -944 | I16: -331 | J16: -505 | K16: -28
A17: Share-based compensation | B17: 406 | C17: 485 | D17: 597 | E17: 638 | F17: 697 | G17: 679 | H17: 800 | I17: 925 | J17: 1059 | K17: 1018
A18: Loss on sale of subsidiary | B18: - | C18: - | D18: - | E18: - | F18: - | G18: - | H18: - | I18: - | J18: - | K18: 8310
A19: Net changes in operating assets and liabilities | B19: 2081 | C19: 183 | D19: 679 | E19: 294 | F19: 683 | G19: 2895 | H19: 1522 | I19: 2246 | J19: 1643 | K19: -808
A20: Accounts receivable and other current assets | B20: -2021 | C20: -2958 | D20: -1692 | E20: -2101 | F20: -1401 | G20: -2883 | H20: -2031 | I20: -3897 | J20: -5558 | K20: -5577
A21: Accounts receivable | B21: -591 | C21: -1357 | D21: -1062 | E21: -1351 | F21: 162 | G21: -688 | H21: -1000 | I21: -2523 | J21: -3114 | K21: -1437
A22: Other assets | B22: -1430 | C22: -1601 | D22: -630 | E22: -750 | F22: -1563 | G22: -2195 | H22: -1031 | I22: -1374 | J22: -2444 | K22: -4140
A23: Medical costs payable | B23: 2585 | C23: 1849 | D23: 1284 | E23: 1831 | F23: 1221 | G23: 152 | H23: 2701 | I23: 4053 | J23: 3482 | K23: 2503
A24: Accounts payable and other accrued liabilities | B24: 1280 | C24: 1494 | D24: 930 | E24: 526 | F24: 733 | G24: 5348 | H24: 1162 | I24: 1964 | J24: 3516 | K24: 2463
A25: Accounts payable and other liabilities | B25: 643 | C25: - | D25: - | E25: - | F25: - | G25: - | H25: - | I25: - | J25: - | K25: -
A26: Other policy liabilities | B26: 637 | C26: - | D26: - | E26: - | F26: - | G26: - | H26: - | I26: - | J26: - | K26: -
A27: Unearned revenues | B27: 237 | C27: -202 | D27: 157 | E27: 38 | F27: 130 | G27: 278 | H27: -310 | I27: 126 | J27: 203 | K27: -197
A28: Cash flows used for investing activities | B28: -18395 | C28: -9355 | D28: -8599 | E28: -12385 | F28: -12699 | G28: -12532 | H28: -10372 | I28: -28476 | J28: -15574 | K28: -20527
A29: Purchases of investments, net of sales and maturities | B29: -6585 | C29: -13266 | D29: -8942 | E29: -7740 | F29: -11040 | G29: -9325 | H29: -8888 | I29: -12744 | J29: -9084 | K29: -17989
A30: Purchases of investments | B30: -9939 | C30: -17547 | D30: -14588 | E30: -14010 | F30: -18131 | G30: -16577 | H30: -17139 | I30: -18825 | J30: -18314 | K30: -27308
A31: Maturities and sales of investments | B31: 3354 | C31: 4281 | D31: 5646 | E31: 6270 | F31: 7091 | G31: 7252 | H31: 8251 | I31: 6081 | J31: 9230 | K31: 9319
A32: Maturities of investments | B32: 3354 | C32: 4281 | D32: 5646 | E32: 6270 | F32: 7091 | G32: 7252 | H32: 8251 | I32: 6081 | J32: 9230 | K32: 9319
A33: Sales of investments | B33: 6054 | C33: 7339 | D33: 4623 | E33: 3641 | F33: 8536 | G33: 6489 | H33: 7045 | I33: 5907 | J33: 7307 | K33: 18514
A34: Cash paid for acquisitions, net | B34: -16308 | C34: -1723 | D34: -2257 | E34: -6223 | F34: -8124 | G34: -7645 | H34: -6075 | I34: -18837 | J34: -10411 | K34: -17553
A35: Cash paid for acquisitions, net excluding cash received from dispositions and other, net | B35: -16164 | C35: -1760 | D35: -2131 | E35: -5997 | F35: -8343 | G35: -7139 | H35: -4821 | I35: -21458 | J35: -10136 | K35: -13408
A36: Loans to providers - cyberattack | B36: - | C36: - | D36: - | E36: - | F36: - | G36: - | H36: - | I36: - | J36: - | K36: -9033
A37: Repayment of care provider loans - cyberattack | B37: - | C37: - | D37: - | E37: - | F37: - | G37: - | H37: - | I37: - | J37: - | K37: 4514
A38: Proceeds from disposal of property, equipment and capitalized software | B38: - | C38: - | D38: - | E38: - | F38: - | G38: - | H38: - | I38: - | J38: - | K38: -
A39: Other, net | B39: -144 | C39: 37 | D39: -126 | E39: -226 | F39: 219 | G39: -506 | H39: -1254 | I39: 2621 | J39: -275 | K39: 374
A40: Cash received from dispositions | B40: - | C40: - | D40: - | E40: - | F40: - | G40: - | H40: - | I40: 3414 | J40: 685 | K40: 2041
A41: Other, net excluding cash received from dispositions | B41: -144 | C41: 37 | D41: -126 | E41: -226 | F41: 219 | G41: - | H41: - | I41: -793 | J41: -960 | K41: -1667
A42: Purchases of property, equipment and capitalized software | B42: -1556 | C42: -1705 | D42: -2023 | E42: -2063 | F42: -2071 | G42: -2051 | H42: -2454 | I42: -2802 | J42: -3386 | K42: -3499
...
