Workbook
Name dr: [2]DCF!$E$18
Name tg: [2]DCF!$E$19
Name tgr: DCF!$E$19
Name UPDATE: '[3]Data Sheet'!$E$1
Name wacc: DCF!$E$18

Sheet Cover
B2: Cover
B3: Hindustan Unilever Limited
B4: Ticker: HINDUNILVR.NS
B5: Sector: FMCG (Personal Care, Home Care, Foods & Refreshments)
B7: Situation Overview
B9: The Bull Case | D9: =HYPERLINK( "https://finance.yahoo.com/quote/"&SUBSTITUTE(#REF!," ","")&"/analysis", "Growth Expectations (Yahoo)") -> #REF!
B10: Market leader in Indian FMCG with dominant brands across personal care, home care, and packaged foods.
B11: Asset-light, high-margin business model delivering consistent EBITDA and cash flow generation.
B12: Strong distribution network (8M+ outlets) providing deep rural and urban penetration.
B13: Premiumization and product innovation driving volume and pricing growth.
B14: Backing from global parent Unilever enables technology, R&D, and brand leverage.
B16: The Bear Case | D16: =HYPERLINK( "https://finance.yahoo.com/quote/"&SUBSTITUTE(#REF!," ","")&"/analysis", "Bear Signals & Red Flags") -> #REF!
B17: High dependence on Indian consumption trends — slowdown impacts volume growth.
B18: Rising raw material inflation (palm oil, crude derivatives) pressures gross margins.
B19: Intense competition from regional FMCG players and D2C brands.
B20: Limited room for margin expansion due to already premium profitability levels.
B21: Valuation risk — trades at consistently high P/E vs peers.

Sheet Trading Comparables
B2: Trading Comparables | D2: Date | E2: =TODAY() -> 46059 | G2: WEBSITE | H2: TICKER
E4: Cr. | F4: Cr. | G4: Cr. | I4: Cr. | J4: Cr. | K4: Cr. | L4: Cr. | M4: Cr. | N4: Cr. | O4: Cr.
X5: Trading Multiples
D6: Current | E6: Share | F6: Enterprise | G6: Market | I6: Revenue | L6: EBITDA | N6: Net Income | Q6: Revenue Growth | S6: EBITDA Margin | U6: Profit Margin | X6: EV / Revenue | Z6: EV / EBITDA | AB6: P / E
B7: Ticker | C7: Company Name | D7: Price | E7: Count | F7: Value | G7: Cap | I7: 2025 | J7: =I7-1 -> 2024 | K7: =J7-1 -> 2023 | L7: =J7 -> 2024 | M7: =K7 -> 2023 | N7: =L7 -> 2024 | O7: =M7 -> 2023 | Q7: =_xlfn.CONCAT(I7,"-",J7) -> 2025-2024 | R7: =_xlfn.CONCAT(J7,"-",K7) -> 2024-2023 | S7: =J7 -> 2024 | T7: =K7 -> 2023 | U7: =S7 -> 2024 | V7: =T7 -> 2023 | X7: =J7 -> 2024 | Y7: =K7 -> 2023 | Z7: =J7 -> 2024 | AA7: =K7 -> 2023 | AB7: =J7 -> 2024 | AC7: =K7 -> 2023
B9: #VALUE! | C9: {=_FV(B9,"Ticker symbol",TRUE)} -> HINDUNILVR | D9: {=_FV(B9,"Price")} -> 2354.4 | E9: {=_FV(B9,"Shares outstanding",TRUE)/10000000} -> 234.9591 | F9: 553106 | G9: {=_FV(B9,"Market cap",TRUE)/10000000} -> 561434.9 | H9: =HYPERLINK("https://www.screener.in/company/"&SUBSTITUTE(C9," ","")&"/consolidated/","Financials") -> Financials | I9: 64243 | J9: 61896 | K9: 60580 | L9: 15875 | M9: 15294 | N9: 10926 | O9: 10282 | Q9: =J9/I9-1 -> -0.036533163 | R9: =K9/J9-1 -> -0.021261471 | S9: =L9/J9 -> 0.25647861 | T9: =M9/K9 -> 0.25245956 | U9: =N9/J9 -> 0.17652191 | V9: =O9/K9 -> 0.16972598 | X9: =$F9/J9 -> 8.936054 | Y9: =$F9/K9 -> 9.130175 | Z9: =$F9/L9 -> 34.841323 | AA9: =$F9/M9 -> 36.164901 | AB9: =$G9/N9 -> 51.385219 | AC9: =$G9/O9 -> 54.603667
B11: #VALUE! | C11: {=_FV(B11,"Ticker symbol",TRUE)} -> NESTLEIND | D11: {=_FV(B11,"Price")} -> 1303.5 | E11: {=_FV(B11,"Shares outstanding",TRUE)/10000000} -> 192.8314 | F11: 251568 | G11: {=_FV(B11,"Market cap",TRUE)/10000000} -> 254286.8 | H11: =HYPERLINK("https://www.screener.in/company/"&SUBSTITUTE(C11," ","")&"/consolidated/","Financials") -> Financials | I11: 21911 | J11: 20202 | K11: 19126 | L11: 6396 | M11: 5717 | N11: 3316 | O11: 2999 | Q11: =J11/I11-1 -> -0.077997353 | R11: =K11/J11-1 -> -0.053262053 | S11: =L11/J11 -> 0.31660232 | T11: =M11/K11 -> 0.29891248 | U11: =N11/J11 -> 0.16414216 | V11: =O11/K11 -> 0.15680226 | X11: =$F11/J11 -> 12.452628 | Y11: =$F11/K11 -> 13.153195 | Z11: =$F11/L11 -> 39.332083 | AA11: =$F11/M11 -> 44.003498 | AB11: =$G11/N11 -> 76.684801 | AC11: =$G11/O11 -> 84.79053
B12: #VALUE! | C12: {=_FV(B12,"Ticker symbol",TRUE)} -> ITC | D12: {=_FV(B12,"Price")} -> 310.2 | E12: {=_FV(B12,"Shares outstanding",TRUE)/10000000} -> 1252.923 | F12: 388657 | G12: {=_FV(B12,"Market cap",TRUE)/10000000} -> 419344.3 | H12: =HYPERLINK("https://www.screener.in/company/"&SUBSTITUTE(C12," ","")&"/consolidated/","Financials") -> Financials | I12: 79809 | J12: 75323 | K12: 70919 | L12: 27337 | M12: 27512 | N12: 35356 | O12: 20751 | Q12: =J12/I12-1 -> -0.056209199 | R12: =K12/J12-1 -> -0.058468197 | S12: =L12/J12 -> 0.36293031 | T12: =M12/K12 -> 0.38793553 | U12: =N12/J12 -> 0.46939182 | V12: =O12/K12 -> 0.29260142 | X12: =$F12/J12 -> 5.1598715 | Y12: =$F12/K12 -> 5.4802944 | Z12: =$F12/L12 -> 14.217251 | AA12: =$F12/M12 -> 14.126817 | AB12: =$G12/N12 -> 11.860626 | AC12: =$G12/O12 -> 20.20839
B13: #VALUE! | C13: {=_FV(B13,"Ticker symbol",TRUE)} -> DABUR | D13: {=_FV(B13,"Price")} -> 504.3 | E13: {=_FV(B13,"Shares outstanding",TRUE)/10000000} -> 177.369 | F13: 89528 | G13: {=_FV(B13,"Market cap",TRUE)/10000000} -> 92595.49 | H13: =HYPERLINK("https://www.screener.in/company/"&SUBSTITUTE(C13," ","")&"/consolidated/","Financials") -> Financials | I13: 12985 | J13: 12404 | K13: 11530 | L13: 2799 | M13: 2473 | N13: 1819 | O13: 1701 | Q13: =J13/I13-1 -> -0.044743935 | R13: =K13/J13-1 -> -0.070461142 | S13: =L13/J13 -> 0.22565302 | T13: =M13/K13 -> 0.21448395 | U13: =N13/J13 -> 0.14664624 | V13: =O13/K13 -> 0.14752819 | X13: =$F13/J13 -> 7.2176717 | Y13: =$F13/K13 -> 7.7647875 | Z13: =$F13/L13 -> 31.985709 | AA13: =$F13/M13 -> 36.202184 | AB13: =$G13/N13 -> 50.904612 | AC13: =$G13/O13 -> 54.435914
B14: #VALUE! | C14: {=_FV(B14,"Ticker symbol",TRUE)} -> MARICO | D14: {=_FV(B14,"Price")} -> 748.3 | E14: {=_FV(B14,"Shares outstanding",TRUE)/10000000} -> 129.5292 | F14: 97171 | G14: {=_FV(B14,"Market cap",TRUE)/10000000} -> 97886.51 | H14: =HYPERLINK("https://www.screener.in/company/"&SUBSTITUTE(C14," ","")&"/consolidated/","Financials") -> Financials | I14: 13008 | J14: 10831 | K14: 9764 | L14: 2217 | M14: 1965 | N14: 1750 | O14: 1322 | Q14: =J14/I14-1 -> -0.16735855 | R14: =K14/J14-1 -> -0.098513526 | S14: =L14/J14 -> 0.20469024 | T14: =M14/K14 -> 0.20124949 | U14: =N14/J14 -> 0.16157326 | V14: =O14/K14 -> 0.13539533 | X14: =$F14/J14 -> 8.9715631 | Y14: =$F14/K14 -> 9.9519664 | Z14: =$F14/L14 -> 43.82995 | AA14: =$F14/M14 -> 49.450891 | AB14: =$G14/N14 -> 55.935149 | AC14: =$G14/O14 -> 74.044259
B15: #VALUE! | C15: {=_FV(B15,"Ticker symbol",TRUE)} -> GODREJIND | D15: {=_FV(B15,"Price")} -> 998.1 | E15: {=_FV(B15,"Shares outstanding",TRUE)/10000000} -> 33.68048 | F15: 33530 | G15: {=_FV(B15,"Market cap",TRUE)/10000000} -> 33707.43 | H15: =HYPERLINK("https://www.screener.in/company/"&SUBSTITUTE(C15," ","")&"/consolidated/","Financials") -> Financials | I15: 20096 | J15: 19657 | K15: 16740 | L15: 1566 | M15: 1815 | N15: 1947 | O15: 1421 | Q15: =J15/I15-1 -> -0.021845143 | R15: =K15/J15-1 -> -0.14839497 | S15: =L15/J15 -> 0.079666277 | T15: =M15/K15 -> 0.10842294 | U15: =N15/J15 -> 0.099048685 | V15: =O15/K15 -> 0.084886499 | X15: =$F15/J15 -> 1.7057537 | Y15: =$F15/K15 -> 2.0029869 | Z15: =$F15/L15 -> 21.411239 | AA15: =$F15/M15 -> 18.473829 | AB15: =$G15/N15 -> 17.312496 | AC15: =$G15/O15 -> 23.720922
B17: Mean | Q17: =AVERAGE(Q11:Q15) -> -0.073630836 | R17: =AVERAGE(R11:R15) -> -0.085819978 | S17: =AVERAGE(S11:S15) -> 0.23790843 | T17: =AVERAGE(T11:T15) -> 0.24220088 | U17: =AVERAGE(U11:U15) -> 0.20816043 | V17: =AVERAGE(V11:V15) -> 0.16344274 | X17: =AVERAGE(X11:X15) -> 7.1014977 | Y17: =AVERAGE(Y11:Y15) -> 7.670646 | Z17: =AVERAGE(Z11:Z15) -> 30.155246 | AA17: =AVERAGE(AA11:AA15) -> 32.451444 | AB17: =AVERAGE(AB11:AB15) -> 42.539537 | AC17: =AVERAGE(AC11:AC15) -> 51.440003
B18: Median | Q18: =MEDIAN(Q11:Q15) -> -0.056209199 | R18: =MEDIAN(R11:R15) -> -0.070461142 | S18: =MEDIAN(S11:S15) -> 0.22565302 | T18: =MEDIAN(T11:T15) -> 0.21448395 | U18: =MEDIAN(U11:U15) -> 0.16157326 | V18: =MEDIAN(V11:V15) -> 0.14752819 | X18: =MEDIAN(X11:X15) -> 7.2176717 | Y18: =MEDIAN(Y11:Y15) -> 7.7647875 | Z18: =MEDIAN(Z11:Z15) -> 31.985709 | AA18: =MEDIAN(AA11:AA15) -> 36.202184 | AB18: =MEDIAN(AB11:AB15) -> 50.904612 | AC18: =MEDIAN(AC11:AC15) -> 54.435914
B20: https://www.nseindia.com/static/market-data/securities-available-for-trading

Sheet WACC
B2: WACC
B4: WACC = % of equity x cost of equity + % of debt x cost of debt x (1 - Tax Rate)
B5: Cost of equity = Risk free rate + Beta x Market Risk Premium
D7: Market | E7: Equity | F7: Risk Free | G7: Beta | H7: Market Risk | I7: Cost of | J7: Debt | K7: Debt | L7: Cost of | M7: Tax Rate | N7: After-tax | O7: WACC
B8: Ticker | C8: Company Name | D8: Cap | E8: Amount | F8: Rate | H8: Premium | I8: Equity | K8: Amount | L8: Debt | N8: Cost of Debt
F9: =HYPERLINK("https://tradingeconomics.com/india/government-bond-yield","India 10Y Yield") -> India 10Y Yield | H9: =HYPERLINK("https://pages.stern.nyu.edu/~adamodar/New_Home_Page/datafile/ctryprem.html","Country Risk Premium") -> Country Risk Premium | J9: =HYPERLINK("https://www.screener.in/company/SBIN/consolidated/#balance-sheet","Debt") -> Debt
B10: #VALUE! | C10: {=_FV(B10,"Ticker symbol",TRUE)} -> HINDUNILVR | D10: {=_FV(B10,"Market cap",TRUE)/10000000} -> 561434.9 | F10: 0.067 | G10: {=_FV(B10,"Beta")} -> 0.7673 | H10: 0.0708 | I10: =F10+G10*H10 -> 0.12132484 | L10: 0.045 | M10: 0.26 | N10: =L10*(1-M10) -> 0.0333 | O10: 0.1152
B12: #VALUE! | C12: {=_FV(B12,"Ticker symbol",TRUE)} -> NESTLEIND | D12: {=_FV(B12,"Market cap",TRUE)/10000000} -> 254286.8 | F12: 0.067 | G12: {=_FV(B12,"Beta")} -> 0.9608 | H12: 0.0708 | I12: =F12+G12*H12 -> 0.13502464 | L12: 0.05 | M12: 0.25 | N12: =L12*(1-M12) -> 0.0375 | O12: 0.0911
B13: #VALUE! | C13: {=_FV(B13,"Ticker symbol",TRUE)} -> ITC | D13: {=_FV(B13,"Market cap",TRUE)/10000000} -> 419344.3 | F13: 0.067 | G13: {=_FV(B13,"Beta")} -> 0.884 | H13: 0.0708 | I13: =F13+G13*H13 -> 0.1295872 | L13: 0.06 | M13: 0.23 | N13: =L13*(1-M13) -> 0.0462 | O13: 0.1293
B14: #VALUE! | C14: {=_FV(B14,"Ticker symbol",TRUE)} -> DABUR | D14: {=_FV(B14,"Market cap",TRUE)/10000000} -> 92595.49 | F14: 0.067 | G14: {=_FV(B14,"Beta")} -> 0.6367 | H14: 0.0708 | I14: =F14+G14*H14 -> 0.11207836 | L14: 0.055 | M14: 0.23 | N14: =L14*(1-M14) -> 0.04235 | O14: 0.1047
B15: #VALUE! | C15: {=_FV(B15,"Ticker symbol",TRUE)} -> MARICO | D15: {=_FV(B15,"Market cap",TRUE)/10000000} -> 97886.51 | F15: 0.067 | G15: {=_FV(B15,"Beta")} -> 0.6124 | H15: 0.0708 | I15: =F15+G15*H15 -> 0.11035792 | L15: 0.04 | M15: 0.22 | N15: =L15*(1-M15) -> 0.0312 | O15: 0.1202
B16: #VALUE! | C16: {=_FV(B16,"Ticker symbol",TRUE)} -> GODREJIND | D16: {=_FV(B16,"Market cap",TRUE)/10000000} -> 33707.43 | F16: 0.067 | G16: {=_FV(B16,"Beta")} -> 0.6063 | H16: 0.0708 | I16: =F16+G16*H16 -> 0.10992604 | L16: 0.07 | M16: 0.21 | N16: =L16*(1-M16) -> 0.0553 | O16: 0.1539
B18: Mean | E18: =AVERAGE(E12:E16) -> #DIV/0! | F18: =AVERAGE(F12:F16) -> 0.067 | G18: =AVERAGE(G12:G16) -> 0.74004 | H18: =AVERAGE(H12:H16) -> 0.0708 | I18: =AVERAGE(I12:I16) -> 0.11939483 | J18: =AVERAGE(J12:J16) -> #DIV/0! | K18: =AVERAGE(K12:K16) -> #DIV/0! | L18: =AVERAGE(L12:L16) -> 0.055 | ... O18: =AVERAGE(O12:O16) -> 0.11984
B19: Median | E19: =MEDIAN(E12:E16) -> #NUM! | F19: =MEDIAN(F12:F16) -> 0.067 | G19: =MEDIAN(G12:G16) -> 0.6367 | H19: =MEDIAN(H12:H16) -> 0.0708 | I19: =MEDIAN(I12:I16) -> 0.11207836 | J19: =MEDIAN(J12:J16) -> #NUM! | K19: =MEDIAN(K12:K16) -> #NUM! | L19: =MEDIAN(L12:L16) -> 0.055 | ... O19: =MEDIAN(O12:O16) -> 0.1202

Sheet DCF
B2: DCF
B4: Ticker | C4: #VALUE! | E4: Current Stock Price | H4: {=_FV(C4,"Price")} -> 2354.4
B5: Date | C5: =TODAY() -> 46059 | E5: Implied Share Price | H5: =P87 -> 657.24552
B6: Year End | C6: 46112 | E6: Upside / (Downside) | H6: =H5/H4-1 -> -0.72084373
A8: x | B8: Assumptions
B10: Switches | G10: Conservative | L10: Base | Q10: Optimistic
B11: Assumptions | G11: Assumptions | I11: Year | J11: Metric | L11: Assumptions | N11: Year | O11: Metric | Q11: Assumptions | S11: Year | T11: Metric
B12: Revenue | E12: 1 | G12: Revenue (% of base) | I12: '26-'27 | J12: 0.85 | Q12: Revenue (% of base) | S12: '26-'27 | T12: 1.15
B13: EBIT | E13: 1 | G13: Revenue (decel.) | I13: '28-'30 | J13: -0.1 | L13: Revenue (decel.) | N13: '28-'30 | O13: -0.05 | Q13: Revenue (decel.) | S13: '28-'30 | T13: -0.025
B14: WACC | E14: 1 | G14: EBIT (% of base) | I14: '26-'27 | J14: 0.95 | Q14: EBIT (% of base) | S14: '26-'27 | T14: 1.05
B15: TGR | E15: 2 | G15: EBIT (growth) | I15: '28-'30 | J15: 0.055 | L15: EBIT (growth) | N15: '28-'30 | O15: 0.07 | Q15: EBIT (growth) | S15: '28-'30 | T15: 0.085
B17: Valuation
B18: WACC | E18: =WACC!O18 -> 0.11984 | G18: WACC | J18: =O18+1% -> 0.15484 | L18: WACC | O18: =T18+2.5% -> 0.14484 | Q18: WACC | T18: =wacc -> 0.11984
B19: TGR | E19: =CHOOSE(E15,J19,O19,T19) -> 0.02 | G19: TGR | J19: 0.015 | L19: TGR | O19: 0.02 | Q19: TGR | T19: 0.025
A21: x | B21: Income Statement (12/31) | E21: 2020 | F21: =E21+1 -> 2021 | G21: =F21+1 -> 2022 | H21: =G21+1 -> 2023 | I21: =H21+1 -> 2024 | J21: =I21+1 -> 2025 | K21: =J21+1 -> 2026 | L21: =K21+1 -> 2027 | M21: =L21+1 -> 2028 | ... O21: =N21+1 -> 2030
B22: Revenue | E22: ='Profit & Loss'!F4 -> 39783 | F22: ='Profit & Loss'!G4 -> 47028 | G22: ='Profit & Loss'!H4 -> 52446 | H22: ='Profit & Loss'!I4 -> 60580 | I22: ='Profit & Loss'!J4 -> 61896 | J22: ='Profit & Loss'!K4 -> 63121 | K22: =J22*(1+K23) -> 64383.42 | L22: =K22*(1+L23) -> 65671.088 | M22: =L22*(1+M23) -> 66984.51 | N22: =M22*(1+N23) -> 68324.2 | O22: =N22*(1+O23) -> 69690.684
B23: % growth | F23: =F22/E22-1 -> 0.18211296 | G23: =G22/F22-1 -> 0.11520796 | H23: =H22/G22-1 -> 0.15509286 | I23: =I22/H22-1 -> 0.021723341 | J23: =J22/I22-1 -> 0.019791263 | K23: 0.02 | L23: 0.02 | M23: 0.02 | N23: 0.02 | O23: 0.02
B25: EBIT | E25: ='Profit & Loss'!F6 -> 9861 | F25: ='Profit & Loss'!G6 -> 11626 | G25: ='Profit & Loss'!H6 -> 12857 | H25: ='Profit & Loss'!I6 -> 14147 | I25: ='Profit & Loss'!J6 -> 14659 | J25: ='Profit & Loss'!K6 -> 14843 | K25: =K22*K26 -> 15452.021 | L25: =L22*L26 -> 15761.061 | M25: =M22*M26 -> 16076.282 | N25: =N22*N26 -> 16397.808 | O25: =O22*O26 -> 16725.764
B26: % of sales | E26: =E25/E22 -> 0.24786969 | F26: =F25/F22 -> 0.24721443 | G26: =G25/G22 -> 0.24514739 | H26: =H25/H22 -> 0.23352592 | I26: =I25/I22 -> 0.23683275 | J26: =J25/J22 -> 0.23515153 | K26: 0.24 | L26: 0.24 | M26: 0.24 | N26: 0.24 | O26: 0.24
B28: Profit before tax | E28: ='Profit & Loss'!B10 -> 6026 | F28: ='Profit & Loss'!C10 -> 6467 | G28: ='Profit & Loss'!D10 -> 7306 | H28: ='Profit & Loss'!E10 -> 8604 | I28: ='Profit & Loss'!F10 -> 9165 | J28: ='Profit & Loss'!G10 -> 10605 | K28: =K22*K29 -> 9657.513 | L28: =L22*L29 -> 9850.6633 | M28: =M22*M29 -> 10047.677 | N28: =N22*N29 -> 10248.63 | O28: =O22*O29 -> 10453.603
B29: % of sales | E29: =E28/E22 -> 0.15147173 | F29: =F28/F22 -> 0.13751382 | G29: =G28/G22 -> 0.13930519 | H29: =H28/H22 -> 0.14202707 | I29: =I28/I22 -> 0.14807096 | J29: =J28/J22 -> 0.16801065 | K29: 0.15 | L29: 0.15 | M29: 0.15 | N29: 0.15 | O29: 0.15
B31: Taxes | E31: ='Profit & Loss'!F11 -> 2409 | F31: ='Profit & Loss'!G11 -> 2606 | G31: ='Profit & Loss'!H11 -> 2987 | H31: ='Profit & Loss'!I11 -> 3201 | I31: ='Profit & Loss'!J11 -> 3644 | J31: ='Profit & Loss'!K11 -> 3744 | K31: =K28*K32 -> 3766.4301 | L31: =L28*L32 -> 2364.1592 | M31: =M28*M32 -> 2411.4424 | N31: =N28*N32 -> 2459.6712 | O31: =O28*O32 -> 2508.8646
B32: Tax rate | E32: =E31/E28 -> 0.39976767 | F32: =F31/F28 -> 0.40296892 | G32: =G31/G28 -> 0.40884205 | H32: =H31/H28 -> 0.37203626 | I32: =I31/I28 -> 0.39759956 | J32: =J31/J28 -> 0.35304102 | K32: 0.39 | L32: 0.24 | M32: 0.24 | N32: 0.24 | O32: 0.24
A34: x | B34: Cash Flow Items (12/31) | E34: 2020 | F34: =E34+1 -> 2021 | G34: =F34+1 -> 2022 | H34: =G34+1 -> 2023 | I34: =H34+1 -> 2024 | J34: =I34+1 -> 2025
B35: D&A | E35: ='Profit & Loss'!F8 -> 1002 | F35: ='Profit & Loss'!G8 -> 1074 | G35: ='Profit & Loss'!H8 -> 1091 | H35: ='Profit & Loss'!I8 -> 1137 | I35: ='Profit & Loss'!J8 -> 1216 | J35: ='Profit & Loss'!K8 -> 1355
B36: % of sales | E36: =E35/E$22 -> 0.025186638 | F36: =F35/F$22 -> 0.022837459 | G36: =G35/G$22 -> 0.020802349 | H36: =H35/H$22 -> 0.01876857 | I36: =I35/I$22 -> 0.019645858 | J36: =J35/J$22 -> 0.021466707
B38: CapEx | E38: =-'Cash Flow'!G23 -> 767 | F38: =-'Cash Flow'!H23 -> 862 | G38: =-'Cash Flow'!I23 -> 4163 | H38: =-'Cash Flow'!J23 -> 1228 | I38: =-'Cash Flow'!K23 -> 1192 | J38: =-'Cash Flow'!L23 -> 1477
B39: % of sales | E39: =E38/E$22 -> 0.019279592 | F39: =F38/F$22 -> 0.018329506 | G39: =G38/G$22 -> 0.079376883 | H39: =H38/H$22 -> 0.020270716 | I39: =I38/I$22 -> 0.01925811 | J39: =J38/J$22 -> 0.023399503
B41: Change in NWC | E41: =-'Cash Flow'!G18 -> 342 | F41: =-'Cash Flow'!H18 -> -411 | G41: =-'Cash Flow'!I18 -> 101 | H41: =-'Cash Flow'!J18 -> 1000 | I41: =-'Cash Flow'!K18 -> 960 | J41: =-'Cash Flow'!L18 -> -1313
B42: % of sales | E42: =E41/E$22 -> 0.0085966368 | F42: =F41/F$22 -> -0.0087394744 | G42: =G41/G$22 -> 0.0019257903 | H42: =H41/H$22 -> 0.016507098 | I42: =I41/I$22 -> 0.015509888 | J42: =J41/J$22 -> -0.020801318
B43: % of change in sales | F43: =F41/(F22-E22) -> -0.056728778 | G43: =G41/(G22-F22) -> 0.018641565 | H43: =H41/(H22-G22) -> 0.12294074 | I43: =I41/(I22-H22) -> 0.72948328 | J43: =J41/(J22-I22) -> -1.0718367
K44: 1 | L44: =K44+1 -> 2 | M44: =L44+1 -> 3 | N44: =M44+1 -> 4 | O44: =N44+1 -> 5 | P44: =O44+1 -> 6
A45: x | B45: DCF (12/31, USD M) | E45: 2019 | F45: =E45+1 -> 2020 | G45: =F45+1 -> 2021 | H45: =G45+1 -> 2022 | I45: =H45+1 -> 2023 | J45: =I45+1 -> 2024 | K45: =J45+1 -> 2025 | L45: =K45+1 -> 2026 | M45: =L45+1 -> 2027 | ... P45: =O45+1 -> 2030
B46: Revenue | E46: =E22 -> 39783 | F46: =F22 -> 47028 | G46: =G22 -> 52446 | H46: =H22 -> 60580 | I46: =I22 -> 61896 | J46: =J22 -> 63121 | K46: =J46*(1+K47) -> 64383.42 | L46: =K46*(1+L47) -> 65477.938 | M46: =L46*(1+M47) -> 66591.063 | N46: =M46*(1+N47) -> 67609.906 | O46: =N46*(1+O47) -> 68540.895 | P46: =O46*(1+P47) -> 69390.322
B47: % growth | F47: =F46/E46-1 -> 0.18211296 | G47: =G46/F46-1 -> 0.11520796 | H47: =H46/G46-1 -> 0.15509286 | I47: =I46/H46-1 -> 0.021723341 | J47: =J46/I46-1 -> 0.019791263 | K47: =OFFSET(K47,$E$12,0) -> 0.02 | L47: =OFFSET(L47,$E$12,0) -> 0.017 | M47: =OFFSET(M47,$E$12,0) -> 0.017 | N47: =OFFSET(N47,$E$12,0) -> 0.0153 | O47: =OFFSET(O47,$E$12,0) -> 0.01377 | P47: =OFFSET(P47,$E$12,0) -> 0.012393
B48: Conservative | K48: =$K$23 -> 0.02 | L48: =L49*$J$12 -> 0.017 | M48: =M49*$J$12 -> 0.017 | N48: =M48*(1+$J$13) -> 0.0153 | O48: =N48*(1+$J$13) -> 0.01377 | P48: =O48*(1+$J$13) -> 0.012393
B49: Base (Street) | K49: =$K$23 -> 0.02 | L49: =L23 -> 0.02 | M49: =M23 -> 0.02 | N49: =M49*(1+$O$13) -> 0.019 | O49: =N49*(1+$O$13) -> 0.01805 | P49: =O49*(1+$O$13) -> 0.0171475
B50: Optimistic | K50: =$K$23 -> 0.02 | L50: =L49*$T$12 -> 0.023 | M50: =M49*$T$12 -> 0.023 | N50: =M50*(1+$T$13) -> 0.022425 | O50: =N50*(1+$T$13) -> 0.021864375 | P50: =O50*(1+$T$13) -> 0.021317766
B52: EBIT | E52: =E25 -> 9861 | F52: =F25 -> 11626 | G52: =G25 -> 12857 | H52: =H25 -> 14147 | I52: =I25 -> 14659 | J52: =J25 -> 14843 | K52: =K53*K46 -> 15452.021 | L52: =L53*L46 -> 14928.97 | M52: =M53*M46 -> 15182.762 | N52: =N53*N46 -> 16262.887 | O52: =O53*O46 -> 17393.602 | P52: =P53*P46 -> 18577.665
B53: % of sales | E53: =E52/E$46 -> 0.24786969 | F53: =F52/F$46 -> 0.24721443 | G53: =G52/G$46 -> 0.24514739 | H53: =H52/H$46 -> 0.23352592 | I53: =I52/I$46 -> 0.23683275 | J53: =J52/J$46 -> 0.23515153 | K53: =OFFSET(K53,$E$13,0) -> 0.24 | L53: =OFFSET(L53,$E$13,0) -> 0.228 | M53: =OFFSET(M53,$E$13,0) -> 0.228 | N53: =OFFSET(N53,$E$13,0) -> 0.24054 | O53: =OFFSET(O53,$E$13,0) -> 0.2537697 | P53: =OFFSET(P53,$E$13,0) -> 0.26772703
...

Sheet Profit & Loss
A1: ='[3]Data Sheet'!B1 -> HINDUSTAN UNILEVER LTD | H1: =UPDATE | M1: SCREENER.IN
A3: Narration | B3: ='[3]Data Sheet'!B16 -> 42460 | C3: ='[3]Data Sheet'!C16 -> 42825 | D3: ='[3]Data Sheet'!D16 -> 43190 | E3: ='[3]Data Sheet'!E16 -> 43555 | F3: ='[3]Data Sheet'!F16 -> 43921 | G3: ='[3]Data Sheet'!G16 -> 44286 | H3: ='[3]Data Sheet'!H16 -> 44651 | I3: ='[3]Data Sheet'!I16 -> 45016 | ... K3: ='[3]Data Sheet'!K16 -> 45747 | L3: Trailing | M3: Best Case | N3: Worst Case
A4: Sales | B4: ='[3]Data Sheet'!B17 -> 32186 | C4: ='[3]Data Sheet'!C17 -> 33162 | D4: ='[3]Data Sheet'!D17 -> 35545 | E4: ='[3]Data Sheet'!E17 -> 39310 | F4: ='[3]Data Sheet'!F17 -> 39783 | G4: ='[3]Data Sheet'!G17 -> 47028 | H4: ='[3]Data Sheet'!H17 -> 52446 | I4: ='[3]Data Sheet'!I17 -> 60580 | ... K4: ='[3]Data Sheet'!K17 -> 63121 | L4: =SUM([3]Quarters!H4:K4) -> 64243 | M4: =$K4+M23*K4 -> 67142.015 | N4: =$K4+N23*L4 -> 64392.45
A5: Expenses | B5: =SUM('[3]Data Sheet'!B18,'[3]Data Sheet'!B20:B24, -1*'[3]Data Sheet'!B19) -> 26276 | C5: =SUM('[3]Data Sheet'!C18,'[3]Data Sheet'!C20:C24, -1*'[3]Data Sheet'!C19) -> 26834 | D5: =SUM('[3]Data Sheet'!D18,'[3]Data Sheet'!D20:D24, -1*'[3]Data Sheet'!D19) -> 28046 | E5: =SUM('[3]Data Sheet'!E18,'[3]Data Sheet'!E20:E24, -1*'[3]Data Sheet'!E19) -> 30430 | F5: =SUM('[3]Data Sheet'!F18,'[3]Data Sheet'!F20:F24, -1*'[3]Data Sheet'!F19) -> 29922 | G5: =SUM('[3]Data Sheet'!G18,'[3]Data Sheet'!G20:G24, -1*'[3]Data Sheet'!G19) -> 35402 | H5: =SUM('[3]Data Sheet'!H18,'[3]Data Sheet'!H20:H24, -1*'[3]Data Sheet'!H19) -> 39589 | I5: =SUM('[3]Data Sheet'!I18,'[3]Data Sheet'!I20:I24, -1*'[3]Data Sheet'!I19) -> 46433 | ... K5: =SUM('[3]Data Sheet'!K18,'[3]Data Sheet'!K20:K24, -1*'[3]Data Sheet'!K19) -> 48278 | L5: =SUM([3]Quarters!H5:K5) -> 49487 | M5: =M4-M6 -> 51351.448 | N5: =N4-N6 -> 49631.079
A6: Operating Profit | B6: =B4-B5 -> 5910 | C6: =C4-C5 -> 6328 | D6: =D4-D5 -> 7499 | E6: =E4-E5 -> 8880 | F6: =F4-F5 -> 9861 | G6: =G4-G5 -> 11626 | H6: =H4-H5 -> 12857 | I6: =I4-I5 -> 14147 | ... K6: =K4-K5 -> 14843 | L6: =SUM([3]Quarters!H6:K6) -> 14756 | M6: =M4*M24 -> 15790.567 | N6: =N4*N24 -> 14761.371
A7: Other Income | B7: ='[3]Data Sheet'!B25 -> 486 | C7: ='[3]Data Sheet'!C25 -> 606 | D7: ='[3]Data Sheet'!D25 -> 353 | E7: ='[3]Data Sheet'!E25 -> 322 | F7: ='[3]Data Sheet'!F25 -> 424 | G7: ='[3]Data Sheet'!G25 -> 170 | H7: ='[3]Data Sheet'!H25 -> 219 | I7: ='[3]Data Sheet'!I25 -> 448 | ... K7: ='[3]Data Sheet'!K25 -> 1322 | L7: =SUM([3]Quarters!H7:K7) -> 1316 | M7: 0 | N7: 0
A8: Depreciation | B8: ='[3]Data Sheet'!B26 -> 353 | C8: ='[3]Data Sheet'!C26 -> 432 | D8: ='[3]Data Sheet'!D26 -> 520 | E8: ='[3]Data Sheet'!E26 -> 565 | F8: ='[3]Data Sheet'!F26 -> 1002 | G8: ='[3]Data Sheet'!G26 -> 1074 | H8: ='[3]Data Sheet'!H26 -> 1091 | I8: ='[3]Data Sheet'!I26 -> 1137 | ... K8: ='[3]Data Sheet'!K26 -> 1355 | L8: =SUM([3]Quarters!H8:K8) -> 1407 | M8: =+$L8 -> 1407 | N8: =+$L8 -> 1407
A9: Interest | B9: ='[3]Data Sheet'!B27 -> 17 | C9: ='[3]Data Sheet'!C27 -> 35 | D9: ='[3]Data Sheet'!D27 -> 26 | E9: ='[3]Data Sheet'!E27 -> 33 | F9: ='[3]Data Sheet'!F27 -> 118 | G9: ='[3]Data Sheet'!G27 -> 117 | H9: ='[3]Data Sheet'!H27 -> 106 | I9: ='[3]Data Sheet'!I27 -> 114 | ... K9: ='[3]Data Sheet'!K27 -> 395 | L9: =SUM([3]Quarters!H9:K9) -> 448 | M9: =+$L9 -> 448 | N9: =+$L9 -> 448
A10: Profit before tax | B10: ='[3]Data Sheet'!B28 -> 6026 | C10: ='[3]Data Sheet'!C28 -> 6467 | D10: ='[3]Data Sheet'!D28 -> 7306 | E10: ='[3]Data Sheet'!E28 -> 8604 | F10: ='[3]Data Sheet'!F28 -> 9165 | G10: ='[3]Data Sheet'!G28 -> 10605 | H10: ='[3]Data Sheet'!H28 -> 11879 | I10: ='[3]Data Sheet'!I28 -> 13344 | ... K10: ='[3]Data Sheet'!K28 -> 14415 | L10: =SUM([3]Quarters!H10:K10) -> 14217 | M10: =M6+M7-SUM(M8:M9) -> 13935.567 | N10: =N6+N7-SUM(N8:N9) -> 12906.371
A11: Tax | B11: ='[3]Data Sheet'!B29 -> 1875 | C11: ='[3]Data Sheet'!C29 -> 1977 | D11: ='[3]Data Sheet'!D29 -> 2079 | E11: ='[3]Data Sheet'!E29 -> 2544 | F11: ='[3]Data Sheet'!F29 -> 2409 | G11: ='[3]Data Sheet'!G29 -> 2606 | H11: ='[3]Data Sheet'!H29 -> 2987 | I11: ='[3]Data Sheet'!I29 -> 3201 | ... K11: ='[3]Data Sheet'!K29 -> 3744 | L11: =SUM([3]Quarters!H11:K11) -> 3291 | M11: =IF($L10>0,$L11/$L10,0) -> 0.23148344 | N11: =IF($L10>0,$L11/$L10,0) -> 0.23148344
A12: Net profit | B12: ='[3]Data Sheet'!B30 -> 4151 | C12: ='[3]Data Sheet'!C30 -> 4476 | D12: ='[3]Data Sheet'!D30 -> 5214 | E12: ='[3]Data Sheet'!E30 -> 6054 | F12: ='[3]Data Sheet'!F30 -> 6748 | G12: ='[3]Data Sheet'!G30 -> 7995 | H12: ='[3]Data Sheet'!H30 -> 8879 | I12: ='[3]Data Sheet'!I30 -> 10120 | ... K12: ='[3]Data Sheet'!K30 -> 10649 | L12: =SUM([3]Quarters!H12:K12) -> 10889 | M12: =M10-M11*M10 -> 10709.714 | N12: =N10-N11*N10 -> 9918.7602
A13: EPS | B13: =IF('[3]Data Sheet'!B93>0,B12/'[3]Data Sheet'!B93,0) -> 19.182957 | C13: =IF('[3]Data Sheet'!C93>0,C12/'[3]Data Sheet'!C93,0) -> 20.681052 | D13: =IF('[3]Data Sheet'!D93>0,D12/'[3]Data Sheet'!D93,0) -> 24.088704 | E13: =IF('[3]Data Sheet'!E93>0,E12/'[3]Data Sheet'!E93,0) -> 27.966924 | F13: =IF('[3]Data Sheet'!F93>0,F12/'[3]Data Sheet'!F93,0) -> 31.171471 | G13: =IF('[3]Data Sheet'!G93>0,G12/'[3]Data Sheet'!G93,0) -> 34.027068 | H13: =IF('[3]Data Sheet'!H93>0,H12/'[3]Data Sheet'!H93,0) -> 37.789411 | I13: =IF('[3]Data Sheet'!I93>0,I12/'[3]Data Sheet'!I93,0) -> 43.071161 | ... K13: =IF('[3]Data Sheet'!K93>0,K12/'[3]Data Sheet'!K93,0) -> 45.322608 | L13: =IF('[3]Data Sheet'!$B6>0,'[3]Profit & Loss'!L12/'[3]Data Sheet'!$B6,0) -> 46.351072 | M13: =IF('[3]Data Sheet'!$B6>0,'[3]Profit & Loss'!M12/'[3]Data Sheet'!$B6,0) -> 45.587907 | N13: =IF('[3]Data Sheet'!$B6>0,'[3]Profit & Loss'!N12/'[3]Data Sheet'!$B6,0) -> 42.221064
A14: Price to earning | B14: =IF(B15>0,B15/B13,"") -> 43.380695 | C14: =IF(C15>0,C15/C13,"") -> 42.193696 | D14: =IF(D15>0,D15/D13,"") -> 52.975453 | E14: =IF(E15>0,E15/E13,"") -> 58.409356 | F14: =IF(F15>0,F15/F13,"") -> 70.571903 | G14: =IF(G15>0,G15/G13,"") -> 68.390258 | H14: =IF(H15>0,H15/H13,"") -> 51.884905 | I14: =IF(I15>0,I15/I13,"") -> 56.892824 | ... K14: =IF(K15>0,K15/K13,"") -> 47.699815 | L14: =IF(L13>0,L15/L13,0) -> 50.794942 | M14: =M25 -> 51.233565 | N14: =N25 -> 50.794942
A15: Price | B15: ='[3]Data Sheet'!B90 -> 832.17 | C15: ='[3]Data Sheet'!C90 -> 872.61 | D15: ='[3]Data Sheet'!D90 -> 1276.11 | E15: ='[3]Data Sheet'!E90 -> 1633.53 | F15: ='[3]Data Sheet'!F90 -> 2199.83 | G15: ='[3]Data Sheet'!G90 -> 2327.12 | H15: ='[3]Data Sheet'!H90 -> 1960.7 | I15: ='[3]Data Sheet'!I90 -> 2450.44 | ... K15: ='[3]Data Sheet'!K90 -> 2161.88 | L15: ='[3]Data Sheet'!B8 -> 2354.4 | M15: =M13*M14 -> 2335.631 | N15: =N13*N14 -> 2144.6165
A17: RATIOS:
A18: Dividend Payout | B18: =IF('[3]Data Sheet'!B30>0, '[3]Data Sheet'!B31/'[3]Data Sheet'!B30, 0) -> 0.83257046 | C18: =IF('[3]Data Sheet'!C30>0, '[3]Data Sheet'!C31/'[3]Data Sheet'!C30, 0) -> 0.82037534 | D18: =IF('[3]Data Sheet'!D30>0, '[3]Data Sheet'!D31/'[3]Data Sheet'!D30, 0) -> 0.82853855 | E18: =IF('[3]Data Sheet'!E30>0, '[3]Data Sheet'!E31/'[3]Data Sheet'!E30, 0) -> 0.78493558 | F18: =IF('[3]Data Sheet'!F30>0, '[3]Data Sheet'!F31/'[3]Data Sheet'!F30, 0) -> 0.80023711 | G18: =IF('[3]Data Sheet'!G30>0, '[3]Data Sheet'!G31/'[3]Data Sheet'!G30, 0) -> 1.1904315 | H18: =IF('[3]Data Sheet'!H30>0, '[3]Data Sheet'!H31/'[3]Data Sheet'!H30, 0) -> 0.89987611 | I18: =IF('[3]Data Sheet'!I30>0, '[3]Data Sheet'!I31/'[3]Data Sheet'!I30, 0) -> 0.90563241 | ... K18: =IF('[3]Data Sheet'!K30>0, '[3]Data Sheet'!K31/'[3]Data Sheet'!K30, 0) -> 1.1695934
A19: OPM | B19: =IF(B6>0,B6/B4,0) -> 0.18362021 | C19: =IF(C6>0,C6/C4,0) -> 0.19082082 | D19: =IF(D6>0,D6/D4,0) -> 0.21097201 | E19: =IF(E6>0,E6/E4,0) -> 0.22589672 | F19: =IF(F6>0,F6/F4,0) -> 0.24786969 | G19: =IF(G6>0,G6/G4,0) -> 0.24721443 | H19: =IF(H6>0,H6/H4,0) -> 0.24514739 | I19: =IF(I6>0,I6/I4,0) -> 0.23352592 | ... L19: =IF(L6>0,L6/L4,0) -> 0.22969039
G22: TRENDS: | H22: 10 YEARS | I22: 7 YEARS | J22: 5 YEARS | K22: 3 YEARS | L22: RECENT | M22: BEST | N22: WORST
G23: Sales Growth | H23: =IF(B4=0,"",POWER($K4/B4,1/9)-1) -> 0.077707146 | I23: =IF(D4=0,"",POWER($K4/D4,1/7)-1) -> 0.0854952 | J23: =IF(F4=0,"",POWER($K4/F4,1/5)-1) -> 0.096718749 | K23: =IF(H4=0,"",POWER($K4/H4, 1/3)-1) -> 0.063703284 | L23: =IF(ISERROR(MAX(IF(J4=0,"",(K4-J4)/J4),IF(K4=0,"",(L4-K4)/K4))),"",MAX(IF(J4=0,"",(K4-J4)/J4),IF(K4=0,"",(L4-K4)/K4))) -> 0.019791263 | M23: =MAX(K23:L23) -> 0.063703284 | N23: =MIN(H23:L23) -> 0.019791263
G24: OPM | H24: =IF(SUM(B4:$K$4)=0,"",SUMPRODUCT(B19:$K$19,B4:$K$4)/SUM(B4:$K$4)) -> 0.22924072 | I24: =IF(SUM(E4:$K$4)=0,"",SUMPRODUCT(E19:$K$19,E4:$K$4)/SUM(E4:$K$4)) -> 0.23855461 | J24: =IF(SUM(G4:$K$4)=0,"",SUMPRODUCT(G19:$K$19,G4:$K$4)/SUM(G4:$K$4)) -> 0.23900011 | K24: =IF(SUM(I4:$K$4)=0, "", SUMPRODUCT(I19:$K$19,I4:$K$4)/SUM(I4:$K$4)) -> 0.2351816 | L24: =L19 -> 0.22969039 | M24: =MAX(K24:L24) -> 0.2351816 | N24: =MIN(H24:L24) -> 0.22924072
G25: Price to Earning | H25: =IF(ISERROR(AVERAGEIF(B14:$L14,">0")),"",AVERAGEIF(B14:$L14,">0")) -> 53.885502 | I25: =IF(ISERROR(AVERAGEIF(E14:$L14,">0")),"",AVERAGEIF(E14:$L14,">0")) -> 56.773835 | J25: =IF(ISERROR(AVERAGEIF(G14:$L14,">0")),"",AVERAGEIF(G14:$L14,">0")) -> 54.20157 | K25: =IF(ISERROR(AVERAGEIF(I14:$L14,">0")),"",AVERAGEIF(I14:$L14,">0")) -> 51.233565 | L25: =L14 -> 50.794942 | M25: =MAX(K25:L25) -> 51.233565 | N25: =MIN(H25:L25) -> 50.794942

Sheet Quarters
A1: ='[3]Profit & Loss'!A1 -> HINDUSTAN UNILEVER LTD | E1: =UPDATE | J1: SCREENER.IN
A3: Narration | B3: ='[3]Data Sheet'!B41 -> 45107 | C3: ='[3]Data Sheet'!C41 -> 45199 | D3: ='[3]Data Sheet'!D41 -> 45291 | E3: ='[3]Data Sheet'!E41 -> 45382 | F3: ='[3]Data Sheet'!F41 -> 45473 | G3: ='[3]Data Sheet'!G41 -> 45565 | H3: ='[3]Data Sheet'!H41 -> 45657 | I3: ='[3]Data Sheet'!I41 -> 45747 | ... K3: ='[3]Data Sheet'!K41 -> 45930
A4: Sales | B4: ='[3]Data Sheet'!B42 -> 15496 | C4: ='[3]Data Sheet'!C42 -> 15623 | D4: ='[3]Data Sheet'!D42 -> 15567 | E4: ='[3]Data Sheet'!E42 -> 15210 | F4: ='[3]Data Sheet'!F42 -> 15707 | G4: ='[3]Data Sheet'!G42 -> 15926 | H4: ='[3]Data Sheet'!H42 -> 15818 | I4: ='[3]Data Sheet'!I42 -> 15670 | ... K4: ='[3]Data Sheet'!K42 -> 16241
A5: Expenses | B5: ='[3]Data Sheet'!B43 -> 11832 | C5: ='[3]Data Sheet'!C43 -> 11828 | D5: ='[3]Data Sheet'!D43 -> 11902 | E5: ='[3]Data Sheet'!E43 -> 11675 | F5: ='[3]Data Sheet'!F43 -> 11965 | G5: ='[3]Data Sheet'!G43 -> 12139 | H5: ='[3]Data Sheet'!H43 -> 12123 | I5: ='[3]Data Sheet'!I43 -> 12052 | ... K5: ='[3]Data Sheet'!K43 -> 12515
A6: Operating Profit | B6: ='[3]Data Sheet'!B50 -> 3664 | C6: ='[3]Data Sheet'!C50 -> 3795 | D6: ='[3]Data Sheet'!D50 -> 3665 | E6: ='[3]Data Sheet'!E50 -> 3535 | F6: ='[3]Data Sheet'!F50 -> 3742 | G6: ='[3]Data Sheet'!G50 -> 3787 | H6: ='[3]Data Sheet'!H50 -> 3695 | I6: ='[3]Data Sheet'!I50 -> 3618 | ... K6: ='[3]Data Sheet'!K50 -> 3726
A7: Other Income | B7: ='[3]Data Sheet'!B44 -> 146 | C7: ='[3]Data Sheet'!C44 -> 178 | D7: ='[3]Data Sheet'!D44 -> 184 | E7: ='[3]Data Sheet'!E44 -> 309 | F7: ='[3]Data Sheet'!F44 -> 209 | G7: ='[3]Data Sheet'!G44 -> 203 | H7: ='[3]Data Sheet'!H44 -> 740 | I7: ='[3]Data Sheet'!I44 -> 171 | ... K7: ='[3]Data Sheet'!K44 -> 331
A8: Depreciation | B8: ='[3]Data Sheet'!B45 -> 286 | C8: ='[3]Data Sheet'!C45 -> 297 | D8: ='[3]Data Sheet'!D45 -> 313 | E8: ='[3]Data Sheet'!E45 -> 320 | F8: ='[3]Data Sheet'!F45 -> 329 | G8: ='[3]Data Sheet'!G45 -> 338 | H8: ='[3]Data Sheet'!H45 -> 341 | I8: ='[3]Data Sheet'!I45 -> 347 | ... K8: ='[3]Data Sheet'!K45 -> 358
A9: Interest | B9: ='[3]Data Sheet'!B46 -> 50 | C9: ='[3]Data Sheet'!C46 -> 88 | D9: ='[3]Data Sheet'!D46 -> 91 | E9: ='[3]Data Sheet'!E46 -> 105 | F9: ='[3]Data Sheet'!F46 -> 93 | G9: ='[3]Data Sheet'!G46 -> 110 | H9: ='[3]Data Sheet'!H46 -> 112 | I9: ='[3]Data Sheet'!I46 -> 80 | ... K9: ='[3]Data Sheet'!K46 -> 129
A10: Profit before tax | B10: ='[3]Data Sheet'!B47 -> 3474 | C10: ='[3]Data Sheet'!C47 -> 3588 | D10: ='[3]Data Sheet'!D47 -> 3445 | E10: ='[3]Data Sheet'!E47 -> 3419 | F10: ='[3]Data Sheet'!F47 -> 3529 | G10: ='[3]Data Sheet'!G47 -> 3542 | H10: ='[3]Data Sheet'!H47 -> 3982 | I10: ='[3]Data Sheet'!I47 -> 3362 | ... K10: ='[3]Data Sheet'!K47 -> 3570
A11: Tax | B11: ='[3]Data Sheet'!B48 -> 918 | C11: ='[3]Data Sheet'!C48 -> 931 | D11: ='[3]Data Sheet'!D48 -> 937 | E11: ='[3]Data Sheet'!E48 -> 858 | F11: ='[3]Data Sheet'!F48 -> 917 | G11: ='[3]Data Sheet'!G48 -> 947 | H11: ='[3]Data Sheet'!H48 -> 993 | I11: ='[3]Data Sheet'!I48 -> 887 | ... K11: ='[3]Data Sheet'!K48 -> 876
A12: Net profit | B12: ='[3]Data Sheet'!B49 -> 2554 | C12: ='[3]Data Sheet'!C49 -> 2656 | D12: ='[3]Data Sheet'!D49 -> 2509 | E12: ='[3]Data Sheet'!E49 -> 2558 | F12: ='[3]Data Sheet'!F49 -> 2610 | G12: ='[3]Data Sheet'!G49 -> 2591 | H12: ='[3]Data Sheet'!H49 -> 2984 | I12: ='[3]Data Sheet'!I49 -> 2464 | ... K12: ='[3]Data Sheet'!K49 -> 2685
A14: OPM | B14: =IF(B4>0,B6/B4,"") -> 0.23644812 | C14: =IF(C4>0,C6/C4,"") -> 0.24291109 | D14: =IF(D4>0,D6/D4,"") -> 0.23543393 | E14: =IF(E4>0,E6/E4,"") -> 0.23241289 | F14: =IF(F4>0,F6/F4,"") -> 0.23823773 | G14: =IF(G4>0,G6/G4,"") -> 0.23778727 | H14: =IF(H4>0,H6/H4,"") -> 0.23359464 | I14: =IF(I4>0,I6/I4,"") -> 0.23088705 | ... K14: =IF(K4>0,K6/K4,"") -> 0.22941937

Sheet Balance Sheet
A1: ='[3]Profit & Loss'!A1 -> HINDUSTAN UNILEVER LTD | E1: =UPDATE | J1: SCREENER.IN
A3: Narration | B3: ='[3]Data Sheet'!B56 -> 42460 | C3: ='[3]Data Sheet'!C56 -> 42825 | D3: ='[3]Data Sheet'!D56 -> 43190 | E3: ='[3]Data Sheet'!E56 -> 43555 | F3: ='[3]Data Sheet'!F56 -> 43921 | G3: ='[3]Data Sheet'!G56 -> 44286 | H3: ='[3]Data Sheet'!H56 -> 44651 | I3: ='[3]Data Sheet'!I56 -> 45016 | ... K3: ='[3]Data Sheet'!K56 -> 45747
A4: Equity Share Capital | B4: ='[3]Data Sheet'!B57 -> 216 | C4: ='[3]Data Sheet'!C57 -> 216 | D4: ='[3]Data Sheet'!D57 -> 216 | E4: ='[3]Data Sheet'!E57 -> 216 | F4: ='[3]Data Sheet'!F57 -> 216 | G4: ='[3]Data Sheet'!G57 -> 235 | H4: ='[3]Data Sheet'!H57 -> 235 | I4: ='[3]Data Sheet'!I57 -> 235 | ... K4: ='[3]Data Sheet'!K57 -> 235
A5: Reserves | B5: ='[3]Data Sheet'!B58 -> 6357 | C5: ='[3]Data Sheet'!C58 -> 6528 | D5: ='[3]Data Sheet'!D58 -> 7065 | E5: ='[3]Data Sheet'!E58 -> 7651 | F5: ='[3]Data Sheet'!F58 -> 8013 | G5: ='[3]Data Sheet'!G58 -> 47439 | H5: ='[3]Data Sheet'!H58 -> 48826 | I5: ='[3]Data Sheet'!I58 -> 50069 | ... K5: ='[3]Data Sheet'!K58 -> 49167
A6: Borrowings | B6: ='[3]Data Sheet'!B59 -> 177 | C6: ='[3]Data Sheet'!C59 -> 277 | D6: ='[3]Data Sheet'!D59 -> 0 | E6: ='[3]Data Sheet'!E59 -> 99 | F6: ='[3]Data Sheet'!F59 -> 0 | G6: ='[3]Data Sheet'!G59 -> 0 | H6: ='[3]Data Sheet'!H59 -> 1043 | I6: ='[3]Data Sheet'!I59 -> 1219 | ... K6: ='[3]Data Sheet'!K59 -> 1648
A7: Other Liabilities | B7: ='[3]Data Sheet'!B60 -> 8043 | C7: ='[3]Data Sheet'!C60 -> 8685 | D7: ='[3]Data Sheet'!D60 -> 10581 | E7: ='[3]Data Sheet'!E60 -> 10663 | F7: ='[3]Data Sheet'!F60 -> 11924 | G7: ='[3]Data Sheet'!G60 -> 21066 | H7: ='[3]Data Sheet'!H60 -> 20402 | I7: ='[3]Data Sheet'!I60 -> 21554 | ... K7: ='[3]Data Sheet'!K60 -> 28813
A8: Total | B8: ='[3]Data Sheet'!B61 -> 14793 | C8: ='[3]Data Sheet'!C61 -> 15706 | D8: ='[3]Data Sheet'!D61 -> 17862 | E8: ='[3]Data Sheet'!E61 -> 18629 | F8: ='[3]Data Sheet'!F61 -> 20153 | G8: ='[3]Data Sheet'!G61 -> 68740 | H8: ='[3]Data Sheet'!H61 -> 70506 | I8: ='[3]Data Sheet'!I61 -> 73077 | ... K8: ='[3]Data Sheet'!K61 -> 79863
A10: Net Block | B10: ='[3]Data Sheet'!B62 -> 3258 | C10: ='[3]Data Sheet'!C62 -> 4419 | D10: ='[3]Data Sheet'!D62 -> 4528 | E10: ='[3]Data Sheet'!E62 -> 4715 | F10: ='[3]Data Sheet'!F62 -> 5479 | G10: ='[3]Data Sheet'!G62 -> 51443 | H10: ='[3]Data Sheet'!H62 -> 51473 | I10: ='[3]Data Sheet'!I62 -> 52678 | ... K10: ='[3]Data Sheet'!K62 -> 54335
A11: Capital Work in Progress | B11: ='[3]Data Sheet'!B63 -> 408 | C11: ='[3]Data Sheet'!C63 -> 229 | D11: ='[3]Data Sheet'!D63 -> 461 | E11: ='[3]Data Sheet'!E63 -> 406 | F11: ='[3]Data Sheet'!F63 -> 597 | G11: ='[3]Data Sheet'!G63 -> 745 | H11: ='[3]Data Sheet'!H63 -> 1313 | I11: ='[3]Data Sheet'!I63 -> 1132 | ... K11: ='[3]Data Sheet'!K63 -> 1009
A12: Investments | B12: ='[3]Data Sheet'!B64 -> 2592 | C12: ='[3]Data Sheet'!C64 -> 3794 | D12: ='[3]Data Sheet'!D64 -> 2873 | E12: ='[3]Data Sheet'!E64 -> 2716 | F12: ='[3]Data Sheet'!F64 -> 1255 | G12: ='[3]Data Sheet'!G64 -> 2709 | H12: ='[3]Data Sheet'!H64 -> 3521 | I12: ='[3]Data Sheet'!I64 -> 2882 | ... K12: ='[3]Data Sheet'!K64 -> 3810
A13: Other Assets | B13: ='[3]Data Sheet'!B65 -> 8535 | C13: ='[3]Data Sheet'!C65 -> 7264 | D13: ='[3]Data Sheet'!D65 -> 10000 | E13: ='[3]Data Sheet'!E65 -> 10792 | F13: ='[3]Data Sheet'!F65 -> 12822 | G13: ='[3]Data Sheet'!G65 -> 13843 | H13: ='[3]Data Sheet'!H65 -> 14199 | I13: ='[3]Data Sheet'!I65 -> 16385 | ... K13: ='[3]Data Sheet'!K65 -> 20709
A14: Total | B14: ='[3]Data Sheet'!B66 -> 14793 | C14: ='[3]Data Sheet'!C66 -> 15706 | D14: ='[3]Data Sheet'!D66 -> 17862 | E14: ='[3]Data Sheet'!E66 -> 18629 | F14: ='[3]Data Sheet'!F66 -> 20153 | G14: ='[3]Data Sheet'!G66 -> 68740 | H14: ='[3]Data Sheet'!H66 -> 70506 | I14: ='[3]Data Sheet'!I66 -> 73077 | ... K14: ='[3]Data Sheet'!K66 -> 79863
A16: Working Capital | B16: =B13-B7 -> 492 | C16: =C13-C7 -> -1421 | D16: =D13-D7 -> -581 | E16: =E13-E7 -> 129 | F16: =F13-F7 -> 898 | G16: =G13-G7 -> -7223 | H16: =H13-H7 -> -6203 | I16: =I13-I7 -> -5169 | ... K16: =K13-K7 -> -8104
A17: Debtors | B17: ='[3]Data Sheet'!B67 -> 1264 | C17: ='[3]Data Sheet'!C67 -> 1085 | D17: ='[3]Data Sheet'!D67 -> 1310 | E17: ='[3]Data Sheet'!E67 -> 1816 | F17: ='[3]Data Sheet'!F67 -> 1149 | G17: ='[3]Data Sheet'!G67 -> 1758 | H17: ='[3]Data Sheet'!H67 -> 2236 | I17: ='[3]Data Sheet'!I67 -> 3079 | ... K17: ='[3]Data Sheet'!K67 -> 3819
A18: Inventory | B18: ='[3]Data Sheet'!B68 -> 2726 | C18: ='[3]Data Sheet'!C68 -> 2541 | D18: ='[3]Data Sheet'!D68 -> 2513 | E18: ='[3]Data Sheet'!E68 -> 2574 | F18: ='[3]Data Sheet'!F68 -> 2767 | G18: ='[3]Data Sheet'!G68 -> 3579 | H18: ='[3]Data Sheet'!H68 -> 4096 | I18: ='[3]Data Sheet'!I68 -> 4251 | ... K18: ='[3]Data Sheet'!K68 -> 4415
A20: Debtor Days | B20: =IF('[3]Profit & Loss'!B4>0,'[3]Balance Sheet'!B17/('[3]Profit & Loss'!B4/365),0) -> 14.334183 | C20: =IF('[3]Profit & Loss'!C4>0,'[3]Balance Sheet'!C17/('[3]Profit & Loss'!C4/365),0) -> 11.942133 | D20: =IF('[3]Profit & Loss'!D4>0,'[3]Balance Sheet'!D17/('[3]Profit & Loss'!D4/365),0) -> 13.451962 | E20: =IF('[3]Profit & Loss'!E4>0,'[3]Balance Sheet'!E17/('[3]Profit & Loss'!E4/365),0) -> 16.861867 | F20: =IF('[3]Profit & Loss'!F4>0,'[3]Balance Sheet'!F17/('[3]Profit & Loss'!F4/365),0) -> 10.541814 | G20: =IF('[3]Profit & Loss'!G4>0,'[3]Balance Sheet'!G17/('[3]Profit & Loss'!G4/365),0) -> 13.644425 | H20: =IF('[3]Profit & Loss'!H4>0,'[3]Balance Sheet'!H17/('[3]Profit & Loss'!H4/365),0) -> 15.56153 | I20: =IF('[3]Profit & Loss'!I4>0,'[3]Balance Sheet'!I17/('[3]Profit & Loss'!I4/365),0) -> 18.551255 | ... K20: =IF('[3]Profit & Loss'!K4>0,'[3]Balance Sheet'!K17/('[3]Profit & Loss'!K4/365),0) -> 22.083538
A21: Inventory Turnover | B21: =IF('[3]Balance Sheet'!B18>0,'[3]Profit & Loss'!B4/'[3]Balance Sheet'!B18,0) -> 11.807043 | C21: =IF('[3]Balance Sheet'!C18>0,'[3]Profit & Loss'!C4/'[3]Balance Sheet'!C18,0) -> 13.050767 | D21: =IF('[3]Balance Sheet'!D18>0,'[3]Profit & Loss'!D4/'[3]Balance Sheet'!D18,0) -> 14.144449 | E21: =IF('[3]Balance Sheet'!E18>0,'[3]Profit & Loss'!E4/'[3]Balance Sheet'!E18,0) -> 15.27195 | F21: =IF('[3]Balance Sheet'!F18>0,'[3]Profit & Loss'!F4/'[3]Balance Sheet'!F18,0) -> 14.377665 | G21: =IF('[3]Balance Sheet'!G18>0,'[3]Profit & Loss'!G4/'[3]Balance Sheet'!G18,0) -> 13.139983 | H21: =IF('[3]Balance Sheet'!H18>0,'[3]Profit & Loss'!H4/'[3]Balance Sheet'!H18,0) -> 12.804199 | I21: =IF('[3]Balance Sheet'!I18>0,'[3]Profit & Loss'!I4/'[3]Balance Sheet'!I18,0) -> 14.250765 | ... K21: =IF('[3]Balance Sheet'!K18>0,'[3]Profit & Loss'!K4/'[3]Balance Sheet'!K18,0) -> 14.296942
A23: Return on Equity | B23: =IF(SUM('[3]Balance Sheet'!B4:B5)>0,'[3]Profit & Loss'!B12/SUM('[3]Balance Sheet'!B4:B5),"") -> 0.6315229 | C23: =IF(SUM('[3]Balance Sheet'!C4:C5)>0,'[3]Profit & Loss'!C12/SUM('[3]Balance Sheet'!C4:C5),"") -> 0.66370107 | D23: =IF(SUM('[3]Balance Sheet'!D4:D5)>0,'[3]Profit & Loss'!D12/SUM('[3]Balance Sheet'!D4:D5),"") -> 0.71611042 | E23: =IF(SUM('[3]Balance Sheet'!E4:E5)>0,'[3]Profit & Loss'!E12/SUM('[3]Balance Sheet'!E4:E5),"") -> 0.76954366 | F23: =IF(SUM('[3]Balance Sheet'!F4:F5)>0,'[3]Profit & Loss'!F12/SUM('[3]Balance Sheet'!F4:F5),"") -> 0.82002673 | G23: =IF(SUM('[3]Balance Sheet'!G4:G5)>0,'[3]Profit & Loss'!G12/SUM('[3]Balance Sheet'!G4:G5),"") -> 0.16770147 | H23: =IF(SUM('[3]Balance Sheet'!H4:H5)>0,'[3]Profit & Loss'!H12/SUM('[3]Balance Sheet'!H4:H5),"") -> 0.18097878 | I23: =IF(SUM('[3]Balance Sheet'!I4:I5)>0,'[3]Profit & Loss'!I12/SUM('[3]Balance Sheet'!I4:I5),"") -> 0.20117684 | ... K23: =IF(SUM('[3]Balance Sheet'!K4:K5)>0,'[3]Profit & Loss'!K12/SUM('[3]Balance Sheet'!K4:K5),"") -> 0.21555807
A24: Return on Capital Emp | C24: =IF((B4+B5+B6+C4+C5+C6)>0,('[3]Profit & Loss'!C10+'[3]Profit & Loss'!C9)*2/(B4+B5+B6+C4+C5+C6),"") -> 0.94430325 | D24: =IF((C4+C5+C6+D4+D5+D6)>0,('[3]Profit & Loss'!D10+'[3]Profit & Loss'!D9)*2/(C4+C5+C6+D4+D5+D6),"") -> 1.0253111 | E24: =IF((D4+D5+D6+E4+E5+E6)>0,('[3]Profit & Loss'!E10+'[3]Profit & Loss'!E9)*2/(D4+D5+D6+E4+E5+E6),"") -> 1.1329442 | F24: =IF((E4+E5+E6+F4+F5+F6)>0,('[3]Profit & Loss'!F10+'[3]Profit & Loss'!F9)*2/(E4+E5+E6+F4+F5+F6),"") -> 1.1464032 | G24: =IF((F4+F5+F6+G4+G5+G6)>0,('[3]Profit & Loss'!G10+'[3]Profit & Loss'!G9)*2/(F4+F5+F6+G4+G5+G6),"") -> 0.38359301 | H24: =IF((G4+G5+G6+H4+H5+H6)>0,('[3]Profit & Loss'!H10+'[3]Profit & Loss'!H9)*2/(G4+G5+G6+H4+H5+H6),"") -> 0.24514717 | I24: =IF((H4+H5+H6+I4+I5+I6)>0,('[3]Profit & Loss'!I10+'[3]Profit & Loss'!I9)*2/(H4+H5+H6+I4+I5+I6),"") -> 0.26485088 | J24: =IF((I4+I5+I6+J4+J5+J6)>0,('[3]Profit & Loss'!J10+'[3]Profit & Loss'!J9)*2/(I4+I5+I6+J4+J5+J6),"") -> 0.27363876 | K24: =IF((J4+J5+J6+K4+K5+K6)>0,('[3]Profit & Loss'!K10+'[3]Profit & Loss'!K9)*2/(J4+J5+J6+K4+K5+K6),"") -> 0.28548847

Sheet Cash Flow
A1: ='[3]Balance Sheet'!A1 -> HINDUSTAN UNILEVER LTD | E1: =UPDATE | J1: SCREENER.IN
A3: Narration | B3: ='[3]Data Sheet'!B81 -> 42460 | C3: ='[3]Data Sheet'!C81 -> 42825 | D3: ='[3]Data Sheet'!D81 -> 43190 | E3: ='[3]Data Sheet'!E81 -> 43555 | F3: ='[3]Data Sheet'!F81 -> 43921 | G3: ='[3]Data Sheet'!G81 -> 44286 | H3: ='[3]Data Sheet'!H81 -> 44651 | I3: ='[3]Data Sheet'!I81 -> 45016 | ... K3: ='[3]Data Sheet'!K81 -> 45747
A4: Cash from Operating Activity | B4: ='[3]Data Sheet'!B82 -> 4171 | C4: ='[3]Data Sheet'!C82 -> 5185 | D4: ='[3]Data Sheet'!D82 -> 6059 | E4: ='[3]Data Sheet'!E82 -> 5800 | F4: ='[3]Data Sheet'!F82 -> 7623 | G4: ='[3]Data Sheet'!G82 -> 9163 | H4: ='[3]Data Sheet'!H82 -> 9048 | I4: ='[3]Data Sheet'!I82 -> 9991 | ... K4: ='[3]Data Sheet'!K82 -> 11886
A5: Cash from Investing Activity | B5: ='[3]Data Sheet'!B83 -> -282 | C5: ='[3]Data Sheet'!C83 -> -1173 | D5: ='[3]Data Sheet'!D83 -> -1063 | E5: ='[3]Data Sheet'!E83 -> -438 | F5: ='[3]Data Sheet'!F83 -> 1791 | G5: ='[3]Data Sheet'!G83 -> -1228 | H5: ='[3]Data Sheet'!H83 -> -1728 | I5: ='[3]Data Sheet'!I83 -> -1484 | ... K5: ='[3]Data Sheet'!K83 -> 6473
A6: Cash from Financing Activity | B6: ='[3]Data Sheet'!B84 -> -3864 | C6: ='[3]Data Sheet'!C84 -> -4214 | D6: ='[3]Data Sheet'!D84 -> -4975 | E6: ='[3]Data Sheet'!E84 -> -5390 | F6: ='[3]Data Sheet'!F84 -> -6819 | G6: ='[3]Data Sheet'!G84 -> -9309 | H6: ='[3]Data Sheet'!H84 -> -8015 | I6: ='[3]Data Sheet'!I84 -> -8953 | ... K6: ='[3]Data Sheet'!K84 -> -13101
A7: Net Cash Flow | B7: ='[3]Data Sheet'!B85 -> 25 | C7: ='[3]Data Sheet'!C85 -> -202 | D7: ='[3]Data Sheet'!D85 -> 21 | E7: ='[3]Data Sheet'!E85 -> -28 | F7: ='[3]Data Sheet'!F85 -> 2595 | G7: ='[3]Data Sheet'!G85 -> -1374 | H7: ='[3]Data Sheet'!H85 -> -695 | I7: ='[3]Data Sheet'!I85 -> -446 | ... K7: ='[3]Data Sheet'!K85 -> 5258
A9: 41699 | B9: 42064 | C9: 42430 | D9: 42795 | E9: 43160 | F9: 43525 | G9: 43891 | H9: 44256 | I9: 44621 | J9: 44986 | K9: 45352 | L9: 45717
A10: Cash from Operating Activity - | B10: 3818 | C10: 3292 | D10: 4171 | E10: 5185 | F10: 6059 | G10: 5800 | H10: 7623 | I10: 9163 | J10: 9048 | K10: 9991 | L10: 15469 | M10: 11886
A11: Profit from operations | B11: 4802 | C11: 5510 | D11: 6025 | E11: 6512 | F11: 7485 | G11: 8909 | H11: 9723 | I11: 11672 | J11: 12829 | K11: 14089 | L11: 14537 | M11: 14942
A12: Receivables | B12: -17 | C12: 3 | D12: -257 | E12: 173 | F12: 0 | G12: 0 | H12: 0 | I12: 0 | J12: 0 | K12: 0 | L12: 0 | M12: 0
A13: Inventory | B13: -201 | C13: 91 | D13: 89 | E13: 37 | F13: -146 | G13: -195 | H13: -331 | I13: -543 | J13: -758 | K13: -339 | L13: 74 | M13: -584
A14: Payables | B14: 546 | C14: -327 | D14: 164 | E14: 501 | F14: 0 | G14: 0 | H14: 0 | I14: 0 | J14: 0 | K14: 0 | L14: 0 | M14: 0
A15: Loans Advances | B15: -4 | C15: -148 | D15: 0 | E15: 0 | F15: 0 | G15: 0 | H15: 0 | I15: 0 | J15: 0 | K15: 0 | L15: 0 | M15: 0
A16: Operating Deposits | B16: 0 | C16: 0 | D16: 0 | E16: -46 | F16: 0 | G16: 0 | H16: 0 | I16: 0 | J16: 0 | K16: 0 | L16: 0 | M16: 0
A17: Other WC items | B17: 81 | C17: 38 | D17: -77 | E17: -99 | F17: 982 | G17: -147 | H17: 742 | I17: 442 | J17: -242 | K17: -621 | L17: 1239 | M17: -204
A18: Working capital changes | B18: 405 | C18: -342 | D18: -81 | E18: 566 | F18: 836 | G18: -342 | H18: 411 | I18: -101 | J18: -1000 | K18: -960 | L18: 1313 | M18: -788
A19: Direct taxes | B19: -1384 | C19: -1862 | D19: -1765 | E19: -1859 | F19: -2264 | G19: -2767 | H19: -2505 | I19: -2407 | J19: -2784 | K19: -3138 | L19: -381 | M19: -2268
A20: Other operating items | B20: -5 | C20: -14 | D20: -8 | E20: -21 | F20: 0 | G20: 0 | H20: 0 | I20: 0 | J20: 0 | K20: 0 | L20: 0 | M20: 0
A21: Exceptional CF items | B21: 0 | C21: 0 | D21: 0 | E21: -13 | F21: 2 | G21: 0 | H21: -6 | I21: -1 | J21: 3 | K21: 0 | L21: 0 | M21: 0
... A42: Net Cash Flow | B42: 383 | C42: -33 | D42: 25 | E42: -202 | F42: 21 | G42: -28 | H42: 2595 | I42: -1374 | J42: -695 | K42: -446 | L42: 111 | M42: 5258

Sheet Data Sheet
A1: COMPANY NAME | B1: HINDUSTAN UNILEVER LTD | E1: =IF(B2<>B3, "A NEW VERSION OF THE WORKSHEET IS AVAILABLE", "")
A2: LATEST VERSION | B2: 2.1 | E2: PLEASE DO NOT MAKE ANY CHANGES TO THIS SHEET
A3: CURRENT VERSION | B3: 2.1
A5: META
A6: Number of shares | B6: =IF(B9>0, B9/B8, 0) -> 234.92445
A7: Face Value | B7: 1
A8: Current Price | B8: 2354.4
A9: Market Capitalization | B9: 553106.12
A15: PROFIT & LOSS
A16: Report Date | B16: 42460 | C16: 42825 | D16: 43190 | E16: 43555 | F16: 43921 | G16: 44286 | H16: 44651 | I16: 45016 | J16: 45382 | K16: 45747
A17: Sales | B17: 32186 | C17: 33162 | D17: 35545 | E17: 39310 | F17: 39783 | G17: 47028 | H17: 52446 | I17: 60580 | J17: 61896 | K17: 63121
A18: Raw Material Cost | B18: 13184 | C18: 13606 | D18: 14233 | E18: 15845 | F18: 15697 | G18: 20141 | H18: 22871 | I18: 28427 | J18: 26822 | K18: 27344
A19: Change in Inventory | B19: -83 | C19: -144 | D19: 72 | E19: -12 | F19: 108 | G19: 405 | H19: 22 | I19: 75 | J19: 11 | K19: 153
A20: Power and Fuel | B20: 309 | C20: 295 | D20: 295 | E20: 308 | F20: 299 | G20: 339 | H20: 318 | I20: 384 | J20: 446 | K20: 427
A21: Other Mfr. Exp | B21: 2966 | C21: 2887 | D21: 2998 | E21: 3041 | F21: 2906 | G21: 2868 | H21: 3354 | I21: 3791 | J21: 3385 | K21: 3834
A22: Employee Cost | B22: 1680 | C22: 1743 | D22: 1860 | E22: 1875 | F22: 1820 | G22: 2358 | H22: 2545 | I22: 2854 | J22: 3009 | K22: 3077
A23: Selling and admin | B23: 6741 | C23: 6689 | D23: 7252 | E23: 7796 | F23: 7620 | G23: 7906 | H23: 8164 | I23: 8785 | J23: 10780 | K23: 10693
A24: Other Expenses | B24: 1313 | C24: 1470 | D24: 1480 | E24: 1553 | F24: 1688 | G24: 2195 | H24: 2359 | I24: 2267 | J24: 2806 | K24: 3056
A25: Other Income | B25: 486 | C25: 606 | D25: 353 | E25: 322 | F25: 424 | G25: 170 | H25: 219 | I25: 448 | J25: 817 | K25: 1322
A26: Depreciation | B26: 353 | C26: 432 | D26: 520 | E26: 565 | F26: 1002 | G26: 1074 | H26: 1091 | I26: 1137 | J26: 1216 | K26: 1355
A27: Interest | B27: 17 | C27: 35 | D27: 26 | E27: 33 | F27: 118 | G27: 117 | H27: 106 | I27: 114 | J27: 334 | K27: 395
... A31: Dividend Amount | B31: 3456 | C31: 3672 | D31: 4320 | E31: 4752 | F31: 5400 | G31: 9517.5 | H31: 7990 | I31: 9165 | J31: 9870 | K31: 12455
A40: Quarters
A41: Report Date | B41: 45107 | C41: 45199 | D41: 45291 | E41: 45382 | F41: 45473 | G41: 45565 | H41: 45657 | I41: 45747 | J41: 45838 | K41: 45930
A42: Sales | B42: 15496 | C42: 15623 | D42: 15567 | E42: 15210 | F42: 15707 | G42: 15926 | H42: 15818 | I42: 15670 | J42: 16514 | K42: 16241
A43: Expenses | B43: 11832 | C43: 11828 | D43: 11902 | E43: 11675 | F43: 11965 | G43: 12139 | H43: 12123 | I43: 12052 | J43: 12797 | K43: 12515
A44: Other Income | B44: 146 | C44: 178 | D44: 184 | E44: 309 | F44: 209 | G44: 203 | H44: 740 | I44: 171 | J44: 74 | K44: 331
A45: Depreciation | B45: 286 | C45: 297 | D45: 313 | E45: 320 | F45: 329 | G45: 338 | H45: 341 | I45: 347 | J45: 361 | K45: 358
A46: Interest | B46: 50 | C46: 88 | D46: 91 | E46: 105 | F46: 93 | G46: 110 | H46: 112 | I46: 80 | J46: 127 | K46: 129
A47: Profit before tax | B47: 3474 | C47: 3588 | D47: 3445 | E47: 3419 | F47: 3529 | G47: 3542 | H47: 3982 | I47: 3362 | J47: 3303 | K47: 3570
A48: Tax | B48: 918 | C48: 931 | D48: 937 | E48: 858 | F48: 917 | G48: 947 | H48: 993 | I48: 887 | J48: 535 | K48: 876
A49: Net profit | B49: 2554 | C49: 2656 | D49: 2509 | E49: 2558 | F49: 2610 | G49: 2591 | H49: 2984 | I49: 2464 | J49: 2756 | K49: 2685
A50: Operating Profit | B50: 3664 | C50: 3795 | D50: 3665 | E50: 3535 | F50: 3742 | G50: 3787 | H50: 3695 | I50: 3618 | J50: 3717 | K50: 3726
A55: BALANCE SHEET
A56: Report Date | B56: 42460 | C56: 42825 | D56: 43190 | E56: 43555 | F56: 43921 | G56: 44286 | H56: 44651 | I56: 45016 | J56: 45382 | K56: 45747
A57: Equity Share Capital | B57: 216 | C57: 216 | D57: 216 | E57: 216 | F57: 216 | G57: 235 | H57: 235 | I57: 235 | J57: 235 | K57: 235
A58: Reserves | B58: 6357 | C58: 6528 | D58: 7065 | E58: 7651 | F58: 8013 | G58: 47439 | H58: 48826 | I58: 50069 | J58: 50983 | K58: 49167
A59: Borrowings | B59: 177 | C59: 277 | E59: 99 | H59: 1043 | I59: 1219 | J59: 1484 | K59: 1648
A60: Other Liabilities | B60: 8043 | C60: 8685 | D60: 10581 | E60: 10663 | F60: 11924 | G60: 21066 | H60: 20402 | I60: 21554 | J60: 25787 | K60: 28813
A61: Total | B61: 14793 | C61: 15706 | D61: 17862 | E61: 18629 | F61: 20153 | G61: 68740 | H61: 70506 | I61: 73077 | J61: 78489 | K61: 79863
...
